Workbook

Sheet START HERE
A1: PCB Tracker — fill these in
A2: Work through the sheets in this order. Everything else is calculated or filled by the dashboard.
B4: Step | C4: Sheet | D4: What to do
B5: 1 | C5: CLIENTS | D5: List every customer once. The name you type here is what appears everywhere else, so settle the naming now — change it later and old rows will not match.
B6: 2 | C6: EMPLOYEES | D6: Your team. The "Name in sheet" column is the short name people actually type as a stage owner. Get this right or the People tab cannot attribute work.
B7: 3 | C7: LISTS | D7: Statuses, reasons and stage names. Already filled — only edit if you want different wording.
B8: 4 | C8: ACTIVE | D8: One row per board still in progress. Fill Customer, Board, Manager, then each stage: Owner, Status, EDC. Leave EDA until the stage finishes.
B9: 5 | C9: COMPLETED | D9: Boards where every stage is done. Same columns. You can leave this empty and let the dashboard move boards here as they close.
B10: 6 | C10: — | D10: Publish the dashboard. From then on the team fills everything through it and these sheets update themselves.
B12: Rules worth knowing
B13: - Cream-coloured cells are yours to fill. White cells with formulas calculate themselves — do not type over them.
B14: - A stage marked NA is not part of that board. It is hidden from the dashboard and excluded from the completion percentage.
B15: - EDC is the expected date of completion. EDA is the actual one. The dashboard writes EDA when someone presses Review done.
B16: - Overall Status decides which sheet a board belongs on. The dashboard reads it back after every save and moves the row.
B17: - Stage owners may combine two people with " + ", for example "Samudra + Sandhya". Both are matched against EMPLOYEES.

Sheet CLIENTS
A1: Clients
A2: One row per customer. The Client name column feeds every dropdown in the tracker.
B4: Client name | C4: Short code | D4: Sector / domain | E4: Account owner | F4: Status | G4: Notes

Sheet EMPLOYEES
A1: Employees
A2: Your roster, pre-filled from what you sent. "Name in sheet" is the short name typed into stage Owner cells — it is the join the People tab depends on.
B4: Employee code | C4: Full name | D4: Function | E4: Experience (yrs) | F4: Billing | G4: Name in sheet | H4: Projects | I4: Plan | J4: Active?
C5: Srinivasa Rao Supuri | D5: Hardware | E5: 14 | F5: Billed | G5: Srinivas | J5: Yes
B6: VC_124 | C6: Galipothu Sunil Kumar | D6: Hardware | E6: 18 | F6: Billed | G6: Sunil | J6: Yes
B7: VC_176 | C7: Jampani Samudralankaiah | D7: Hardware | E7: 6.4 | F7: Billed | G7: Samudra | J7: Yes
B8: VC_183 | C8: Varimadla Anjaneyulu | D8: Hardware | E8: 8.1 | F8: Billed | G8: Anji | J8: Yes
B9: VC_224 | C9: Chintha Vivek Sai | D9: Hardware | E9: 0.1 | F9: Billed | G9: Vivek | J9: Yes
B10: VC_161 | C10: Veeresh Meeniga | D10: Hardware | E10: 2.7 | F10: Billed | G10: Veeresh | J10: Yes
B11: VC_141 | C11: Ravada Ramesh | D11: Hardware | E11: 4.2 | F11: Billed | G11: Ramesh | J11: Yes
B12: VC_163 | C12: Ruka Nandi Vardhan Reddy | D12: Hardware | E12: 2.7 | F12: Billed | G12: Vardhan | J12: Yes
B13: VC_196 | C13: Keerthi Sepana | D13: Hardware | E13: 1.3 | F13: Billed | G13: Keerthi | J13: Yes
B14: VC_200 | C14: Harika Kunduru | D14: Hardware | E14: 4 | F14: Billed | G14: Harika | J14: Yes
B15: VC_229 | C15: Bommi Sandhya | D15: Hardware | G15: Sandhya | J15: Yes
C16: Naveen | D16: Hardware | G16: Naveen | J16: Yes
C17: Rajesh | D17: Hardware | G17: Rajesh Sir | J17: Yes
B44: Fabrication vendors | C44: Listed separately so fab work is never counted as someone's workload.
B45: PCB Power
B46: JLC
B47: Micropack

Sheet PROCESS DEFINITION
A1: Process definition
A2: Seven stages, four columns each: Owner, Status, EDC, EDA.
B4: Stage | C4: Stage name | D4: Completed when | E4: Owner column holds
B5: S1 | C5: Schematic Design | D5: Schematic released and netlist handed to layout. | E5: A design engineer
B6: S2 | C6: PCB Layout / Design | D6: DRC and DFM clean, Gerber released. | E6: A layout engineer
B7: S3 | C7: SI & PI Simulation | D7: All in-scope interfaces within margin and report shared. | E7: A simulation engineer
B8: S4 | C8: Bare-PCB Fabrication | D8: Bare boards received and inspected. | E8: The fabricator, not a staff member
B9: S5 | C9: Assembly | D9: Board populated and inspected. | E9: A hardware engineer
B10: S6 | C10: Bring-up | D10: Board powers up, passes validation and is handed over. | E10: A hardware engineer
B11: S7 | C11: BOM Procurement | D11: Parts sourced, or alternates agreed. | E11: A design engineer
B13: Column contract the dashboard depends on
B14: - The field header row must contain "Project / Board", with the stage group headers in the row directly above.
B15: - Each stage group header must keep its name — SCHEMATIC, PCB LAYOUT, SI & PI, BARE-PCB FAB, ASSEMBLY, BRING-UP, BOM PROCUREMENT. The S<n> prefix is ignored.
B16: - Within a stage block the order is Owner, Status, EDC, EDA.
B17: - Owner values must match the "Name in sheet" column on EMPLOYEES. Two people combine with " + ".
B18: - Customer values must match the Client name column on CLIENTS.

Sheet ACTIVE
A1: ACTIVE / PENDING BOARDS
A2: One row per board still in progress. Fill the cream cells; the white ones calculate. EDC is the expected date of completion, EDA the actual one.
A4: RESPIN QUEUE | H4: =COUNTIF(COMPLETED!$AU$6:$AU$255,"Yes")&" board(s) flagged for respin" -> 0 board(s) flagged for respin
A5: # | B5: Customer | C5: Board | D5: Re-entry Stage | E5: Respin Reason | F5: Raised On | G5: Pull in and start at
A6: 1 | B6: =IFERROR(INDEX(COMPLETED!$B$6:$B$255,MATCH(1,COMPLETED!$AZ$6:$AZ$255,0))&"","") | C6: =IFERROR(INDEX(COMPLETED!$C$6:$C$255,MATCH(1,COMPLETED!$AZ$6:$AZ$255,0))&"","") | D6: =IFERROR(INDEX(COMPLETED!$AV$6:$AV$255,MATCH(1,COMPLETED!$AZ$6:$AZ$255,0))&"","") | E6: =IFERROR(INDEX(COMPLETED!$AW$6:$AW$255,MATCH(1,COMPLETED!$AZ$6:$AZ$255,0))&"","") | F6: =IFERROR(INDEX(COMPLETED!$AX$6:$AX$255,MATCH(1,COMPLETED!$AZ$6:$AZ$255,0))&"","") | G6: =IF(C6="","",IF(D6="","Re-entry stage not set","start at "&D6))
A7: 2 | B7: =IFERROR(INDEX(COMPLETED!$B$6:$B$255,MATCH(2,COMPLETED!$AZ$6:$AZ$255,0))&"","") | C7: =IFERROR(INDEX(COMPLETED!$C$6:$C$255,MATCH(2,COMPLETED!$AZ$6:$AZ$255,0))&"","") | D7: =IFERROR(INDEX(COMPLETED!$AV$6:$AV$255,MATCH(2,COMPLETED!$AZ$6:$AZ$255,0))&"","") | E7: =IFERROR(INDEX(COMPLETED!$AW$6:$AW$255,MATCH(2,COMPLETED!$AZ$6:$AZ$255,0))&"","") | F7: =IFERROR(INDEX(COMPLETED!$AX$6:$AX$255,MATCH(2,COMPLETED!$AZ$6:$AZ$255,0))&"","") | G7: =IF(C7="","",IF(D7="","Re-entry stage not set","start at "&D7))
A8: 3 | B8: =IFERROR(INDEX(COMPLETED!$B$6:$B$255,MATCH(3,COMPLETED!$AZ$6:$AZ$255,0))&"","") | C8: =IFERROR(INDEX(COMPLETED!$C$6:$C$255,MATCH(3,COMPLETED!$AZ$6:$AZ$255,0))&"","") | D8: =IFERROR(INDEX(COMPLETED!$AV$6:$AV$255,MATCH(3,COMPLETED!$AZ$6:$AZ$255,0))&"","") | E8: =IFERROR(INDEX(COMPLETED!$AW$6:$AW$255,MATCH(3,COMPLETED!$AZ$6:$AZ$255,0))&"","") | F8: =IFERROR(INDEX(COMPLETED!$AX$6:$AX$255,MATCH(3,COMPLETED!$AZ$6:$AZ$255,0))&"","") | G8: =IF(C8="","",IF(D8="","Re-entry stage not set","start at "&D8))
A9: 4 | B9: =IFERROR(INDEX(COMPLETED!$B$6:$B$255,MATCH(4,COMPLETED!$AZ$6:$AZ$255,0))&"","") | C9: =IFERROR(INDEX(COMPLETED!$C$6:$C$255,MATCH(4,COMPLETED!$AZ$6:$AZ$255,0))&"","") | D9: =IFERROR(INDEX(COMPLETED!$AV$6:$AV$255,MATCH(4,COMPLETED!$AZ$6:$AZ$255,0))&"","") | E9: =IFERROR(INDEX(COMPLETED!$AW$6:$AW$255,MATCH(4,COMPLETED!$AZ$6:$AZ$255,0))&"","") | F9: =IFERROR(INDEX(COMPLETED!$AX$6:$AX$255,MATCH(4,COMPLETED!$AZ$6:$AZ$255,0))&"","") | G9: =IF(C9="","",IF(D9="","Re-entry stage not set","start at "&D9))
A10: 5 | B10: =IFERROR(INDEX(COMPLETED!$B$6:$B$255,MATCH(5,COMPLETED!$AZ$6:$AZ$255,0))&"","") | C10: =IFERROR(INDEX(COMPLETED!$C$6:$C$255,MATCH(5,COMPLETED!$AZ$6:$AZ$255,0))&"","") | D10: =IFERROR(INDEX(COMPLETED!$AV$6:$AV$255,MATCH(5,COMPLETED!$AZ$6:$AZ$255,0))&"","") | E10: =IFERROR(INDEX(COMPLETED!$AW$6:$AW$255,MATCH(5,COMPLETED!$AZ$6:$AZ$255,0))&"","") | F10: =IFERROR(INDEX(COMPLETED!$AX$6:$AX$255,MATCH(5,COMPLETED!$AZ$6:$AZ$255,0))&"","") | G10: =IF(C10="","",IF(D10="","Re-entry stage not set","start at "&D10))
A11: 6 | B11: =IFERROR(INDEX(COMPLETED!$B$6:$B$255,MATCH(6,COMPLETED!$AZ$6:$AZ$255,0))&"","") | C11: =IFERROR(INDEX(COMPLETED!$C$6:$C$255,MATCH(6,COMPLETED!$AZ$6:$AZ$255,0))&"","") | D11: =IFERROR(INDEX(COMPLETED!$AV$6:$AV$255,MATCH(6,COMPLETED!$AZ$6:$AZ$255,0))&"","") | E11: =IFERROR(INDEX(COMPLETED!$AW$6:$AW$255,MATCH(6,COMPLETED!$AZ$6:$AZ$255,0))&"","") | F11: =IFERROR(INDEX(COMPLETED!$AX$6:$AX$255,MATCH(6,COMPLETED!$AZ$6:$AZ$255,0))&"","") | G11: =IF(C11="","",IF(D11="","Re-entry stage not set","start at "&D11))
A12: 7 | B12: =IFERROR(INDEX(COMPLETED!$B$6:$B$255,MATCH(7,COMPLETED!$AZ$6:$AZ$255,0))&"","") | C12: =IFERROR(INDEX(COMPLETED!$C$6:$C$255,MATCH(7,COMPLETED!$AZ$6:$AZ$255,0))&"","") | D12: =IFERROR(INDEX(COMPLETED!$AV$6:$AV$255,MATCH(7,COMPLETED!$AZ$6:$AZ$255,0))&"","") | E12: =IFERROR(INDEX(COMPLETED!$AW$6:$AW$255,MATCH(7,COMPLETED!$AZ$6:$AZ$255,0))&"","") | F12: =IFERROR(INDEX(COMPLETED!$AX$6:$AX$255,MATCH(7,COMPLETED!$AZ$6:$AZ$255,0))&"","") | G12: =IF(C12="","",IF(D12="","Re-entry stage not set","start at "&D12))
A13: 8 | B13: =IFERROR(INDEX(COMPLETED!$B$6:$B$255,MATCH(8,COMPLETED!$AZ$6:$AZ$255,0))&"","") | C13: =IFERROR(INDEX(COMPLETED!$C$6:$C$255,MATCH(8,COMPLETED!$AZ$6:$AZ$255,0))&"","") | D13: =IFERROR(INDEX(COMPLETED!$AV$6:$AV$255,MATCH(8,COMPLETED!$AZ$6:$AZ$255,0))&"","") | E13: =IFERROR(INDEX(COMPLETED!$AW$6:$AW$255,MATCH(8,COMPLETED!$AZ$6:$AZ$255,0))&"","") | F13: =IFERROR(INDEX(COMPLETED!$AX$6:$AX$255,MATCH(8,COMPLETED!$AZ$6:$AZ$255,0))&"","") | G13: =IF(C13="","",IF(D13="","Re-entry stage not set","start at "&D13))
A15: PROJECT | E15: PROCESS ROLL-UP | L15: S1 SCHEMATIC | Q15: S2 PCB LAYOUT | V15: S3 SI & PI | AA15: S4 BARE-PCB FAB | AF15: S5 ASSEMBLY | AK15: S6 BRING-UP | AP15: S7 BOM PROCUREMENT | AU15: RESPIN ORIGIN | AY15: FOLLOW-UP
A16: S.No | B16: Customer | C16: Project / Board | D16: Project Manager | E16: Current Stage | F16: Overall Status | G16: EDC (current stage) | H16: Days | I16: Stages Done | J16: Stages In Scope | K16: % Complete | L16: Owner | M16: Status | N16: EDC | O16: EDA | P16: Comment | Q16: Owner | R16: Status | S16: EDC | T16: EDA | U16: Comment | V16: Owner | W16: Status | X16: EDC | Y16: EDA | Z16: Comment | AA16: Fabricator | AB16: Status | AC16: EDC | AD16: EDA | AE16: Comment | AF16: Owner | AG16: Status | AH16: EDC | AI16: EDA | AJ16: Comment | AK16: Owner | AL16: Status | AM16: EDC | AN16: EDA | AO16: Comment | AP16: Owner | AQ16: Status | AR16: EDC | AS16: EDA | AT16: Comment | AU16: Rev / Respin No. | AV16: Re-entered At | AW16: Respin Reason | AX16: Raised On | AY16: Hold / delay reason | AZ16: Reason check | BA16: Notes / Data Check
A17: =IF($C17="","",COUNTA($C$17:$C17)) | E17: =IF($C17="","",IF(NOT(OR(M17="Completed",M17="NA",M17="Cancelled")),"S1 Schematic",IF(NOT(OR(R17="Completed",R17="NA",R17="Cancelled")),"S2 PCB Layout",IF(NOT(OR(W17="Completed",W17="NA",W17="Cancelled")),"S3 SI & PI",IF(NOT(OR(AB17="Completed",AB17="NA",AB17="Cancelled")),"S4 Bare-PCB Fab",IF(NOT(OR(AG17="Completed",AG17="NA",AG17="Cancelled")),"S5 Assembly",IF(NOT(OR(AL17="Completed",AL17="NA",AL17="Cancelled")),"S6 Bring-up",IF(NOT(OR(AQ17="Completed",AQ17="NA",AQ17="Cancelled")),"S7 BOM Procurement","All Stages Closed")))))))) | F17: =IF($C17="","",IF(COUNTIF(M17,"Cancelled")+COUNTIF(R17,"Cancelled")+COUNTIF(W17,"Cancelled")+COUNTIF(AB17,"Cancelled")+COUNTIF(AG17,"Cancelled")+COUNTIF(AL17,"Cancelled")+COUNTIF(AQ17,"Cancelled")>0,"Cancelled",IF(E17="All Stages Closed","Completed",IF(E17="S1 Schematic",M17,IF(E17="S2 PCB Layout",R17,IF(E17="S3 SI & PI",W17,IF(E17="S4 Bare-PCB Fab",AB17,IF(E17="S5 Assembly",AG17,IF(E17="S6 Bring-up",AL17,AQ17))))))))) | G17: =IF($C17="","",IF(E17="All Stages Closed","",IF(E17="S1 Schematic",IF(N17="","Not added",N17),IF(E17="S2 PCB Layout",IF(S17="","Not added",S17),IF(E17="S3 SI & PI",IF(X17="","Not added",X17),IF(E17="S4 Bare-PCB Fab",IF(AC17="","Not added",AC17),IF(E17="S5 Assembly",IF(AH17="","Not added",AH17),IF(E17="S6 Bring-up",IF(AM17="","Not added",AM17),IF(AR17="","Not added",AR17))))))))) | H17: =IF($C17="","",IF(OR(F17="Completed",F17="Cancelled"),"",IF(NOT(ISNUMBER(G17)),"No date set",IF(TODAY()>G17,TODAY()-G17&" days late",G17-TODAY()&" days left")))) | I17: =IF($C17="","",COUNTIF(M17,"Completed")+COUNTIF(R17,"Completed")+COUNTIF(W17,"Completed")+COUNTIF(AB17,"Completed")+COUNTIF(AG17,"Completed")+COUNTIF(AL17,"Completed")+COUNTIF(AQ17,"Completed")) | J17: =IF($C17="","",7-(COUNTIF(M17,"NA")+COUNTIF(R17,"NA")+COUNTIF(W17,"NA")+COUNTIF(AB17,"NA")+COUNTIF(AG17,"NA")+COUNTIF(AL17,"NA")+COUNTIF(AQ17,"NA"))) | K17: =IFERROR(I17/J17,"") | AZ17: =IF($C17="","",IF(OR(F17="Completed",F17="Cancelled"),"",IF(AND(OR(F17="On Hold",ISNUMBER(VALUE(LEFT(H17,2)))),AY17=""),"Reason not given","")))
A18: =IF($C18="","",COUNTA($C$17:$C18)) | E18: =IF($C18="","",IF(NOT(OR(M18="Completed",M18="NA",M18="Cancelled")),"S1 Schematic",IF(NOT(OR(R18="Completed",R18="NA",R18="Cancelled")),"S2 PCB Layout",IF(NOT(OR(W18="Completed",W18="NA",W18="Cancelled")),"S3 SI & PI",IF(NOT(OR(AB18="Completed",AB18="NA",AB18="Cancelled")),"S4 Bare-PCB Fab",IF(NOT(OR(AG18="Completed",AG18="NA",AG18="Cancelled")),"S5 Assembly",IF(NOT(OR(AL18="Completed",AL18="NA",AL18="Cancelled")),"S6 Bring-up",IF(NOT(OR(AQ18="Completed",AQ18="NA",AQ18="Cancelled")),"S7 BOM Procurement","All Stages Closed")))))))) | F18: =IF($C18="","",IF(COUNTIF(M18,"Cancelled")+COUNTIF(R18,"Cancelled")+COUNTIF(W18,"Cancelled")+COUNTIF(AB18,"Cancelled")+COUNTIF(AG18,"Cancelled")+COUNTIF(AL18,"Cancelled")+COUNTIF(AQ18,"Cancelled")>0,"Cancelled",IF(E18="All Stages Closed","Completed",IF(E18="S1 Schematic",M18,IF(E18="S2 PCB Layout",R18,IF(E18="S3 SI & PI",W18,IF(E18="S4 Bare-PCB Fab",AB18,IF(E18="S5 Assembly",AG18,IF(E18="S6 Bring-up",AL18,AQ18))))))))) | G18: =IF($C18="","",IF(E18="All Stages Closed","",IF(E18="S1 Schematic",IF(N18="","Not added",N18),IF(E18="S2 PCB Layout",IF(S18="","Not added",S18),IF(E18="S3 SI & PI",IF(X18="","Not added",X18),IF(E18="S4 Bare-PCB Fab",IF(AC18="","Not added",AC18),IF(E18="S5 Assembly",IF(AH18="","Not added",AH18),IF(E18="S6 Bring-up",IF(AM18="","Not added",AM18),IF(AR18="","Not added",AR18))))))))) | H18: =IF($C18="","",IF(OR(F18="Completed",F18="Cancelled"),"",IF(NOT(ISNUMBER(G18)),"No date set",IF(TODAY()>G18,TODAY()-G18&" days late",G18-TODAY()&" days left")))) | I18: =IF($C18="","",COUNTIF(M18,"Completed")+COUNTIF(R18,"Completed")+COUNTIF(W18,"Completed")+COUNTIF(AB18,"Completed")+COUNTIF(AG18,"Completed")+COUNTIF(AL18,"Completed")+COUNTIF(AQ18,"Completed")) | J18: =IF($C18="","",7-(COUNTIF(M18,"NA")+COUNTIF(R18,"NA")+COUNTIF(W18,"NA")+COUNTIF(AB18,"NA")+COUNTIF(AG18,"NA")+COUNTIF(AL18,"NA")+COUNTIF(AQ18,"NA"))) | K18: =IFERROR(I18/J18,"") | AZ18: =IF($C18="","",IF(OR(F18="Completed",F18="Cancelled"),"",IF(AND(OR(F18="On Hold",ISNUMBER(VALUE(LEFT(H18,2)))),AY18=""),"Reason not given","")))
A19: =IF($C19="","",COUNTA($C$17:$C19)) | E19: =IF($C19="","",IF(NOT(OR(M19="Completed",M19="NA",M19="Cancelled")),"S1 Schematic",IF(NOT(OR(R19="Completed",R19="NA",R19="Cancelled")),"S2 PCB Layout",IF(NOT(OR(W19="Completed",W19="NA",W19="Cancelled")),"S3 SI & PI",IF(NOT(OR(AB19="Completed",AB19="NA",AB19="Cancelled")),"S4 Bare-PCB Fab",IF(NOT(OR(AG19="Completed",AG19="NA",AG19="Cancelled")),"S5 Assembly",IF(NOT(OR(AL19="Completed",AL19="NA",AL19="Cancelled")),"S6 Bring-up",IF(NOT(OR(AQ19="Completed",AQ19="NA",AQ19="Cancelled")),"S7 BOM Procurement","All Stages Closed")))))))) | F19: =IF($C19="","",IF(COUNTIF(M19,"Cancelled")+COUNTIF(R19,"Cancelled")+COUNTIF(W19,"Cancelled")+COUNTIF(AB19,"Cancelled")+COUNTIF(AG19,"Cancelled")+COUNTIF(AL19,"Cancelled")+COUNTIF(AQ19,"Cancelled")>0,"Cancelled",IF(E19="All Stages Closed","Completed",IF(E19="S1 Schematic",M19,IF(E19="S2 PCB Layout",R19,IF(E19="S3 SI & PI",W19,IF(E19="S4 Bare-PCB Fab",AB19,IF(E19="S5 Assembly",AG19,IF(E19="S6 Bring-up",AL19,AQ19))))))))) | G19: =IF($C19="","",IF(E19="All Stages Closed","",IF(E19="S1 Schematic",IF(N19="","Not added",N19),IF(E19="S2 PCB Layout",IF(S19="","Not added",S19),IF(E19="S3 SI & PI",IF(X19="","Not added",X19),IF(E19="S4 Bare-PCB Fab",IF(AC19="","Not added",AC19),IF(E19="S5 Assembly",IF(AH19="","Not added",AH19),IF(E19="S6 Bring-up",IF(AM19="","Not added",AM19),IF(AR19="","Not added",AR19))))))))) | H19: =IF($C19="","",IF(OR(F19="Completed",F19="Cancelled"),"",IF(NOT(ISNUMBER(G19)),"No date set",IF(TODAY()>G19,TODAY()-G19&" days late",G19-TODAY()&" days left")))) | I19: =IF($C19="","",COUNTIF(M19,"Completed")+COUNTIF(R19,"Completed")+COUNTIF(W19,"Completed")+COUNTIF(AB19,"Completed")+COUNTIF(AG19,"Completed")+COUNTIF(AL19,"Completed")+COUNTIF(AQ19,"Completed")) | J19: =IF($C19="","",7-(COUNTIF(M19,"NA")+COUNTIF(R19,"NA")+COUNTIF(W19,"NA")+COUNTIF(AB19,"NA")+COUNTIF(AG19,"NA")+COUNTIF(AL19,"NA")+COUNTIF(AQ19,"NA"))) | K19: =IFERROR(I19/J19,"") | AZ19: =IF($C19="","",IF(OR(F19="Completed",F19="Cancelled"),"",IF(AND(OR(F19="On Hold",ISNUMBER(VALUE(LEFT(H19,2)))),AY19=""),"Reason not given","")))
A20: =IF($C20="","",COUNTA($C$17:$C20)) | E20: =IF($C20="","",IF(NOT(OR(M20="Completed",M20="NA",M20="Cancelled")),"S1 Schematic",IF(NOT(OR(R20="Completed",R20="NA",R20="Cancelled")),"S2 PCB Layout",IF(NOT(OR(W20="Completed",W20="NA",W20="Cancelled")),"S3 SI & PI",IF(NOT(OR(AB20="Completed",AB20="NA",AB20="Cancelled")),"S4 Bare-PCB Fab",IF(NOT(OR(AG20="Completed",AG20="NA",AG20="Cancelled")),"S5 Assembly",IF(NOT(OR(AL20="Completed",AL20="NA",AL20="Cancelled")),"S6 Bring-up",IF(NOT(OR(AQ20="Completed",AQ20="NA",AQ20="Cancelled")),"S7 BOM Procurement","All Stages Closed")))))))) | F20: =IF($C20="","",IF(COUNTIF(M20,"Cancelled")+COUNTIF(R20,"Cancelled")+COUNTIF(W20,"Cancelled")+COUNTIF(AB20,"Cancelled")+COUNTIF(AG20,"Cancelled")+COUNTIF(AL20,"Cancelled")+COUNTIF(AQ20,"Cancelled")>0,"Cancelled",IF(E20="All Stages Closed","Completed",IF(E20="S1 Schematic",M20,IF(E20="S2 PCB Layout",R20,IF(E20="S3 SI & PI",W20,IF(E20="S4 Bare-PCB Fab",AB20,IF(E20="S5 Assembly",AG20,IF(E20="S6 Bring-up",AL20,AQ20))))))))) | G20: =IF($C20="","",IF(E20="All Stages Closed","",IF(E20="S1 Schematic",IF(N20="","Not added",N20),IF(E20="S2 PCB Layout",IF(S20="","Not added",S20),IF(E20="S3 SI & PI",IF(X20="","Not added",X20),IF(E20="S4 Bare-PCB Fab",IF(AC20="","Not added",AC20),IF(E20="S5 Assembly",IF(AH20="","Not added",AH20),IF(E20="S6 Bring-up",IF(AM20="","Not added",AM20),IF(AR20="","Not added",AR20))))))))) | H20: =IF($C20="","",IF(OR(F20="Completed",F20="Cancelled"),"",IF(NOT(ISNUMBER(G20)),"No date set",IF(TODAY()>G20,TODAY()-G20&" days late",G20-TODAY()&" days left")))) | I20: =IF($C20="","",COUNTIF(M20,"Completed")+COUNTIF(R20,"Completed")+COUNTIF(W20,"Completed")+COUNTIF(AB20,"Completed")+COUNTIF(AG20,"Completed")+COUNTIF(AL20,"Completed")+COUNTIF(AQ20,"Completed")) | J20: =IF($C20="","",7-(COUNTIF(M20,"NA")+COUNTIF(R20,"NA")+COUNTIF(W20,"NA")+COUNTIF(AB20,"NA")+COUNTIF(AG20,"NA")+COUNTIF(AL20,"NA")+COUNTIF(AQ20,"NA"))) | K20: =IFERROR(I20/J20,"") | AZ20: =IF($C20="","",IF(OR(F20="Completed",F20="Cancelled"),"",IF(AND(OR(F20="On Hold",ISNUMBER(VALUE(LEFT(H20,2)))),AY20=""),"Reason not given","")))
A21: =IF($C21="","",COUNTA($C$17:$C21)) | E21: =IF($C21="","",IF(NOT(OR(M21="Completed",M21="NA",M21="Cancelled")),"S1 Schematic",IF(NOT(OR(R21="Completed",R21="NA",R21="Cancelled")),"S2 PCB Layout",IF(NOT(OR(W21="Completed",W21="NA",W21="Cancelled")),"S3 SI & PI",IF(NOT(OR(AB21="Completed",AB21="NA",AB21="Cancelled")),"S4 Bare-PCB Fab",IF(NOT(OR(AG21="Completed",AG21="NA",AG21="Cancelled")),"S5 Assembly",IF(NOT(OR(AL21="Completed",AL21="NA",AL21="Cancelled")),"S6 Bring-up",IF(NOT(OR(AQ21="Completed",AQ21="NA",AQ21="Cancelled")),"S7 BOM Procurement","All Stages Closed")))))))) | F21: =IF($C21="","",IF(COUNTIF(M21,"Cancelled")+COUNTIF(R21,"Cancelled")+COUNTIF(W21,"Cancelled")+COUNTIF(AB21,"Cancelled")+COUNTIF(AG21,"Cancelled")+COUNTIF(AL21,"Cancelled")+COUNTIF(AQ21,"Cancelled")>0,"Cancelled",IF(E21="All Stages Closed","Completed",IF(E21="S1 Schematic",M21,IF(E21="S2 PCB Layout",R21,IF(E21="S3 SI & PI",W21,IF(E21="S4 Bare-PCB Fab",AB21,IF(E21="S5 Assembly",AG21,IF(E21="S6 Bring-up",AL21,AQ21))))))))) | G21: =IF($C21="","",IF(E21="All Stages Closed","",IF(E21="S1 Schematic",IF(N21="","Not added",N21),IF(E21="S2 PCB Layout",IF(S21="","Not added",S21),IF(E21="S3 SI & PI",IF(X21="","Not added",X21),IF(E21="S4 Bare-PCB Fab",IF(AC21="","Not added",AC21),IF(E21="S5 Assembly",IF(AH21="","Not added",AH21),IF(E21="S6 Bring-up",IF(AM21="","Not added",AM21),IF(AR21="","Not added",AR21))))))))) | H21: =IF($C21="","",IF(OR(F21="Completed",F21="Cancelled"),"",IF(NOT(ISNUMBER(G21)),"No date set",IF(TODAY()>G21,TODAY()-G21&" days late",G21-TODAY()&" days left")))) | I21: =IF($C21="","",COUNTIF(M21,"Completed")+COUNTIF(R21,"Completed")+COUNTIF(W21,"Completed")+COUNTIF(AB21,"Completed")+COUNTIF(AG21,"Completed")+COUNTIF(AL21,"Completed")+COUNTIF(AQ21,"Completed")) | J21: =IF($C21="","",7-(COUNTIF(M21,"NA")+COUNTIF(R21,"NA")+COUNTIF(W21,"NA")+COUNTIF(AB21,"NA")+COUNTIF(AG21,"NA")+COUNTIF(AL21,"NA")+COUNTIF(AQ21,"NA"))) | K21: =IFERROR(I21/J21,"") | AZ21: =IF($C21="","",IF(OR(F21="Completed",F21="Cancelled"),"",IF(AND(OR(F21="On Hold",ISNUMBER(VALUE(LEFT(H21,2)))),AY21=""),"Reason not given","")))
A22: =IF($C22="","",COUNTA($C$17:$C22)) | E22: =IF($C22="","",IF(NOT(OR(M22="Completed",M22="NA",M22="Cancelled")),"S1 Schematic",IF(NOT(OR(R22="Completed",R22="NA",R22="Cancelled")),"S2 PCB Layout",IF(NOT(OR(W22="Completed",W22="NA",W22="Cancelled")),"S3 SI & PI",IF(NOT(OR(AB22="Completed",AB22="NA",AB22="Cancelled")),"S4 Bare-PCB Fab",IF(NOT(OR(AG22="Completed",AG22="NA",AG22="Cancelled")),"S5 Assembly",IF(NOT(OR(AL22="Completed",AL22="NA",AL22="Cancelled")),"S6 Bring-up",IF(NOT(OR(AQ22="Completed",AQ22="NA",AQ22="Cancelled")),"S7 BOM Procurement","All Stages Closed")))))))) | F22: =IF($C22="","",IF(COUNTIF(M22,"Cancelled")+COUNTIF(R22,"Cancelled")+COUNTIF(W22,"Cancelled")+COUNTIF(AB22,"Cancelled")+COUNTIF(AG22,"Cancelled")+COUNTIF(AL22,"Cancelled")+COUNTIF(AQ22,"Cancelled")>0,"Cancelled",IF(E22="All Stages Closed","Completed",IF(E22="S1 Schematic",M22,IF(E22="S2 PCB Layout",R22,IF(E22="S3 SI & PI",W22,IF(E22="S4 Bare-PCB Fab",AB22,IF(E22="S5 Assembly",AG22,IF(E22="S6 Bring-up",AL22,AQ22))))))))) | G22: =IF($C22="","",IF(E22="All Stages Closed","",IF(E22="S1 Schematic",IF(N22="","Not added",N22),IF(E22="S2 PCB Layout",IF(S22="","Not added",S22),IF(E22="S3 SI & PI",IF(X22="","Not added",X22),IF(E22="S4 Bare-PCB Fab",IF(AC22="","Not added",AC22),IF(E22="S5 Assembly",IF(AH22="","Not added",AH22),IF(E22="S6 Bring-up",IF(AM22="","Not added",AM22),IF(AR22="","Not added",AR22))))))))) | H22: =IF($C22="","",IF(OR(F22="Completed",F22="Cancelled"),"",IF(NOT(ISNUMBER(G22)),"No date set",IF(TODAY()>G22,TODAY()-G22&" days late",G22-TODAY()&" days left")))) | I22: =IF($C22="","",COUNTIF(M22,"Completed")+COUNTIF(R22,"Completed")+COUNTIF(W22,"Completed")+COUNTIF(AB22,"Completed")+COUNTIF(AG22,"Completed")+COUNTIF(AL22,"Completed")+COUNTIF(AQ22,"Completed")) | J22: =IF($C22="","",7-(COUNTIF(M22,"NA")+COUNTIF(R22,"NA")+COUNTIF(W22,"NA")+COUNTIF(AB22,"NA")+COUNTIF(AG22,"NA")+COUNTIF(AL22,"NA")+COUNTIF(AQ22,"NA"))) | K22: =IFERROR(I22/J22,"") | AZ22: =IF($C22="","",IF(OR(F22="Completed",F22="Cancelled"),"",IF(AND(OR(F22="On Hold",ISNUMBER(VALUE(LEFT(H22,2)))),AY22=""),"Reason not given","")))
A23: =IF($C23="","",COUNTA($C$17:$C23)) | E23: =IF($C23="","",IF(NOT(OR(M23="Completed",M23="NA",M23="Cancelled")),"S1 Schematic",IF(NOT(OR(R23="Completed",R23="NA",R23="Cancelled")),"S2 PCB Layout",IF(NOT(OR(W23="Completed",W23="NA",W23="Cancelled")),"S3 SI & PI",IF(NOT(OR(AB23="Completed",AB23="NA",AB23="Cancelled")),"S4 Bare-PCB Fab",IF(NOT(OR(AG23="Completed",AG23="NA",AG23="Cancelled")),"S5 Assembly",IF(NOT(OR(AL23="Completed",AL23="NA",AL23="Cancelled")),"S6 Bring-up",IF(NOT(OR(AQ23="Completed",AQ23="NA",AQ23="Cancelled")),"S7 BOM Procurement","All Stages Closed")))))))) | F23: =IF($C23="","",IF(COUNTIF(M23,"Cancelled")+COUNTIF(R23,"Cancelled")+COUNTIF(W23,"Cancelled")+COUNTIF(AB23,"Cancelled")+COUNTIF(AG23,"Cancelled")+COUNTIF(AL23,"Cancelled")+COUNTIF(AQ23,"Cancelled")>0,"Cancelled",IF(E23="All Stages Closed","Completed",IF(E23="S1 Schematic",M23,IF(E23="S2 PCB Layout",R23,IF(E23="S3 SI & PI",W23,IF(E23="S4 Bare-PCB Fab",AB23,IF(E23="S5 Assembly",AG23,IF(E23="S6 Bring-up",AL23,AQ23))))))))) | G23: =IF($C23="","",IF(E23="All Stages Closed","",IF(E23="S1 Schematic",IF(N23="","Not added",N23),IF(E23="S2 PCB Layout",IF(S23="","Not added",S23),IF(E23="S3 SI & PI",IF(X23="","Not added",X23),IF(E23="S4 Bare-PCB Fab",IF(AC23="","Not added",AC23),IF(E23="S5 Assembly",IF(AH23="","Not added",AH23),IF(E23="S6 Bring-up",IF(AM23="","Not added",AM23),IF(AR23="","Not added",AR23))))))))) | H23: =IF($C23="","",IF(OR(F23="Completed",F23="Cancelled"),"",IF(NOT(ISNUMBER(G23)),"No date set",IF(TODAY()>G23,TODAY()-G23&" days late",G23-TODAY()&" days left")))) | I23: =IF($C23="","",COUNTIF(M23,"Completed")+COUNTIF(R23,"Completed")+COUNTIF(W23,"Completed")+COUNTIF(AB23,"Completed")+COUNTIF(AG23,"Completed")+COUNTIF(AL23,"Completed")+COUNTIF(AQ23,"Completed")) | J23: =IF($C23="","",7-(COUNTIF(M23,"NA")+COUNTIF(R23,"NA")+COUNTIF(W23,"NA")+COUNTIF(AB23,"NA")+COUNTIF(AG23,"NA")+COUNTIF(AL23,"NA")+COUNTIF(AQ23,"NA"))) | K23: =IFERROR(I23/J23,"") | AZ23: =IF($C23="","",IF(OR(F23="Completed",F23="Cancelled"),"",IF(AND(OR(F23="On Hold",ISNUMBER(VALUE(LEFT(H23,2)))),AY23=""),"Reason not given","")))
A24: =IF($C24="","",COUNTA($C$17:$C24)) | E24: =IF($C24="","",IF(NOT(OR(M24="Completed",M24="NA",M24="Cancelled")),"S1 Schematic",IF(NOT(OR(R24="Completed",R24="NA",R24="Cancelled")),"S2 PCB Layout",IF(NOT(OR(W24="Completed",W24="NA",W24="Cancelled")),"S3 SI & PI",IF(NOT(OR(AB24="Completed",AB24="NA",AB24="Cancelled")),"S4 Bare-PCB Fab",IF(NOT(OR(AG24="Completed",AG24="NA",AG24="Cancelled")),"S5 Assembly",IF(NOT(OR(AL24="Completed",AL24="NA",AL24="Cancelled")),"S6 Bring-up",IF(NOT(OR(AQ24="Completed",AQ24="NA",AQ24="Cancelled")),"S7 BOM Procurement","All Stages Closed")))))))) | F24: =IF($C24="","",IF(COUNTIF(M24,"Cancelled")+COUNTIF(R24,"Cancelled")+COUNTIF(W24,"Cancelled")+COUNTIF(AB24,"Cancelled")+COUNTIF(AG24,"Cancelled")+COUNTIF(AL24,"Cancelled")+COUNTIF(AQ24,"Cancelled")>0,"Cancelled",IF(E24="All Stages Closed","Completed",IF(E24="S1 Schematic",M24,IF(E24="S2 PCB Layout",R24,IF(E24="S3 SI & PI",W24,IF(E24="S4 Bare-PCB Fab",AB24,IF(E24="S5 Assembly",AG24,IF(E24="S6 Bring-up",AL24,AQ24))))))))) | G24: =IF($C24="","",IF(E24="All Stages Closed","",IF(E24="S1 Schematic",IF(N24="","Not added",N24),IF(E24="S2 PCB Layout",IF(S24="","Not added",S24),IF(E24="S3 SI & PI",IF(X24="","Not added",X24),IF(E24="S4 Bare-PCB Fab",IF(AC24="","Not added",AC24),IF(E24="S5 Assembly",IF(AH24="","Not added",AH24),IF(E24="S6 Bring-up",IF(AM24="","Not added",AM24),IF(AR24="","Not added",AR24))))))))) | H24: =IF($C24="","",IF(OR(F24="Completed",F24="Cancelled"),"",IF(NOT(ISNUMBER(G24)),"No date set",IF(TODAY()>G24,TODAY()-G24&" days late",G24-TODAY()&" days left")))) | I24: =IF($C24="","",COUNTIF(M24,"Completed")+COUNTIF(R24,"Completed")+COUNTIF(W24,"Completed")+COUNTIF(AB24,"Completed")+COUNTIF(AG24,"Completed")+COUNTIF(AL24,"Completed")+COUNTIF(AQ24,"Completed")) | J24: =IF($C24="","",7-(COUNTIF(M24,"NA")+COUNTIF(R24,"NA")+COUNTIF(W24,"NA")+COUNTIF(AB24,"NA")+COUNTIF(AG24,"NA")+COUNTIF(AL24,"NA")+COUNTIF(AQ24,"NA"))) | K24: =IFERROR(I24/J24,"") | AZ24: =IF($C24="","",IF(OR(F24="Completed",F24="Cancelled"),"",IF(AND(OR(F24="On Hold",ISNUMBER(VALUE(LEFT(H24,2)))),AY24=""),"Reason not given","")))
A25: =IF($C25="","",COUNTA($C$17:$C25)) | E25: =IF($C25="","",IF(NOT(OR(M25="Completed",M25="NA",M25="Cancelled")),"S1 Schematic",IF(NOT(OR(R25="Completed",R25="NA",R25="Cancelled")),"S2 PCB Layout",IF(NOT(OR(W25="Completed",W25="NA",W25="Cancelled")),"S3 SI & PI",IF(NOT(OR(AB25="Completed",AB25="NA",AB25="Cancelled")),"S4 Bare-PCB Fab",IF(NOT(OR(AG25="Completed",AG25="NA",AG25="Cancelled")),"S5 Assembly",IF(NOT(OR(AL25="Completed",AL25="NA",AL25="Cancelled")),"S6 Bring-up",IF(NOT(OR(AQ25="Completed",AQ25="NA",AQ25="Cancelled")),"S7 BOM Procurement","All Stages Closed")))))))) | F25: =IF($C25="","",IF(COUNTIF(M25,"Cancelled")+COUNTIF(R25,"Cancelled")+COUNTIF(W25,"Cancelled")+COUNTIF(AB25,"Cancelled")+COUNTIF(AG25,"Cancelled")+COUNTIF(AL25,"Cancelled")+COUNTIF(AQ25,"Cancelled")>0,"Cancelled",IF(E25="All Stages Closed","Completed",IF(E25="S1 Schematic",M25,IF(E25="S2 PCB Layout",R25,IF(E25="S3 SI & PI",W25,IF(E25="S4 Bare-PCB Fab",AB25,IF(E25="S5 Assembly",AG25,IF(E25="S6 Bring-up",AL25,AQ25))))))))) | G25: =IF($C25="","",IF(E25="All Stages Closed","",IF(E25="S1 Schematic",IF(N25="","Not added",N25),IF(E25="S2 PCB Layout",IF(S25="","Not added",S25),IF(E25="S3 SI & PI",IF(X25="","Not added",X25),IF(E25="S4 Bare-PCB Fab",IF(AC25="","Not added",AC25),IF(E25="S5 Assembly",IF(AH25="","Not added",AH25),IF(E25="S6 Bring-up",IF(AM25="","Not added",AM25),IF(AR25="","Not added",AR25))))))))) | H25: =IF($C25="","",IF(OR(F25="Completed",F25="Cancelled"),"",IF(NOT(ISNUMBER(G25)),"No date set",IF(TODAY()>G25,TODAY()-G25&" days late",G25-TODAY()&" days left")))) | I25: =IF($C25="","",COUNTIF(M25,"Completed")+COUNTIF(R25,"Completed")+COUNTIF(W25,"Completed")+COUNTIF(AB25,"Completed")+COUNTIF(AG25,"Completed")+COUNTIF(AL25,"Completed")+COUNTIF(AQ25,"Completed")) | J25: =IF($C25="","",7-(COUNTIF(M25,"NA")+COUNTIF(R25,"NA")+COUNTIF(W25,"NA")+COUNTIF(AB25,"NA")+COUNTIF(AG25,"NA")+COUNTIF(AL25,"NA")+COUNTIF(AQ25,"NA"))) | K25: =IFERROR(I25/J25,"") | AZ25: =IF($C25="","",IF(OR(F25="Completed",F25="Cancelled"),"",IF(AND(OR(F25="On Hold",ISNUMBER(VALUE(LEFT(H25,2)))),AY25=""),"Reason not given","")))
A26: =IF($C26="","",COUNTA($C$17:$C26)) | E26: =IF($C26="","",IF(NOT(OR(M26="Completed",M26="NA",M26="Cancelled")),"S1 Schematic",IF(NOT(OR(R26="Completed",R26="NA",R26="Cancelled")),"S2 PCB Layout",IF(NOT(OR(W26="Completed",W26="NA",W26="Cancelled")),"S3 SI & PI",IF(NOT(OR(AB26="Completed",AB26="NA",AB26="Cancelled")),"S4 Bare-PCB Fab",IF(NOT(OR(AG26="Completed",AG26="NA",AG26="Cancelled")),"S5 Assembly",IF(NOT(OR(AL26="Completed",AL26="NA",AL26="Cancelled")),"S6 Bring-up",IF(NOT(OR(AQ26="Completed",AQ26="NA",AQ26="Cancelled")),"S7 BOM Procurement","All Stages Closed")))))))) | F26: =IF($C26="","",IF(COUNTIF(M26,"Cancelled")+COUNTIF(R26,"Cancelled")+COUNTIF(W26,"Cancelled")+COUNTIF(AB26,"Cancelled")+COUNTIF(AG26,"Cancelled")+COUNTIF(AL26,"Cancelled")+COUNTIF(AQ26,"Cancelled")>0,"Cancelled",IF(E26="All Stages Closed","Completed",IF(E26="S1 Schematic",M26,IF(E26="S2 PCB Layout",R26,IF(E26="S3 SI & PI",W26,IF(E26="S4 Bare-PCB Fab",AB26,IF(E26="S5 Assembly",AG26,IF(E26="S6 Bring-up",AL26,AQ26))))))))) | G26: =IF($C26="","",IF(E26="All Stages Closed","",IF(E26="S1 Schematic",IF(N26="","Not added",N26),IF(E26="S2 PCB Layout",IF(S26="","Not added",S26),IF(E26="S3 SI & PI",IF(X26="","Not added",X26),IF(E26="S4 Bare-PCB Fab",IF(AC26="","Not added",AC26),IF(E26="S5 Assembly",IF(AH26="","Not added",AH26),IF(E26="S6 Bring-up",IF(AM26="","Not added",AM26),IF(AR26="","Not added",AR26))))))))) | H26: =IF($C26="","",IF(OR(F26="Completed",F26="Cancelled"),"",IF(NOT(ISNUMBER(G26)),"No date set",IF(TODAY()>G26,TODAY()-G26&" days late",G26-TODAY()&" days left")))) | I26: =IF($C26="","",COUNTIF(M26,"Completed")+COUNTIF(R26,"Completed")+COUNTIF(W26,"Completed")+COUNTIF(AB26,"Completed")+COUNTIF(AG26,"Completed")+COUNTIF(AL26,"Completed")+COUNTIF(AQ26,"Completed")) | J26: =IF($C26="","",7-(COUNTIF(M26,"NA")+COUNTIF(R26,"NA")+COUNTIF(W26,"NA")+COUNTIF(AB26,"NA")+COUNTIF(AG26,"NA")+COUNTIF(AL26,"NA")+COUNTIF(AQ26,"NA"))) | K26: =IFERROR(I26/J26,"") | AZ26: =IF($C26="","",IF(OR(F26="Completed",F26="Cancelled"),"",IF(AND(OR(F26="On Hold",ISNUMBER(VALUE(LEFT(H26,2)))),AY26=""),"Reason not given","")))
A27: =IF($C27="","",COUNTA($C$17:$C27)) | E27: =IF($C27="","",IF(NOT(OR(M27="Completed",M27="NA",M27="Cancelled")),"S1 Schematic",IF(NOT(OR(R27="Completed",R27="NA",R27="Cancelled")),"S2 PCB Layout",IF(NOT(OR(W27="Completed",W27="NA",W27="Cancelled")),"S3 SI & PI",IF(NOT(OR(AB27="Completed",AB27="NA",AB27="Cancelled")),"S4 Bare-PCB Fab",IF(NOT(OR(AG27="Completed",AG27="NA",AG27="Cancelled")),"S5 Assembly",IF(NOT(OR(AL27="Completed",AL27="NA",AL27="Cancelled")),"S6 Bring-up",IF(NOT(OR(AQ27="Completed",AQ27="NA",AQ27="Cancelled")),"S7 BOM Procurement","All Stages Closed")))))))) | F27: =IF($C27="","",IF(COUNTIF(M27,"Cancelled")+COUNTIF(R27,"Cancelled")+COUNTIF(W27,"Cancelled")+COUNTIF(AB27,"Cancelled")+COUNTIF(AG27,"Cancelled")+COUNTIF(AL27,"Cancelled")+COUNTIF(AQ27,"Cancelled")>0,"Cancelled",IF(E27="All Stages Closed","Completed",IF(E27="S1 Schematic",M27,IF(E27="S2 PCB Layout",R27,IF(E27="S3 SI & PI",W27,IF(E27="S4 Bare-PCB Fab",AB27,IF(E27="S5 Assembly",AG27,IF(E27="S6 Bring-up",AL27,AQ27))))))))) | G27: =IF($C27="","",IF(E27="All Stages Closed","",IF(E27="S1 Schematic",IF(N27="","Not added",N27),IF(E27="S2 PCB Layout",IF(S27="","Not added",S27),IF(E27="S3 SI & PI",IF(X27="","Not added",X27),IF(E27="S4 Bare-PCB Fab",IF(AC27="","Not added",AC27),IF(E27="S5 Assembly",IF(AH27="","Not added",AH27),IF(E27="S6 Bring-up",IF(AM27="","Not added",AM27),IF(AR27="","Not added",AR27))))))))) | H27: =IF($C27="","",IF(OR(F27="Completed",F27="Cancelled"),"",IF(NOT(ISNUMBER(G27)),"No date set",IF(TODAY()>G27,TODAY()-G27&" days late",G27-TODAY()&" days left")))) | I27: =IF($C27="","",COUNTIF(M27,"Completed")+COUNTIF(R27,"Completed")+COUNTIF(W27,"Completed")+COUNTIF(AB27,"Completed")+COUNTIF(AG27,"Completed")+COUNTIF(AL27,"Completed")+COUNTIF(AQ27,"Completed")) | J27: =IF($C27="","",7-(COUNTIF(M27,"NA")+COUNTIF(R27,"NA")+COUNTIF(W27,"NA")+COUNTIF(AB27,"NA")+COUNTIF(AG27,"NA")+COUNTIF(AL27,"NA")+COUNTIF(AQ27,"NA"))) | K27: =IFERROR(I27/J27,"") | AZ27: =IF($C27="","",IF(OR(F27="Completed",F27="Cancelled"),"",IF(AND(OR(F27="On Hold",ISNUMBER(VALUE(LEFT(H27,2)))),AY27=""),"Reason not given","")))
A28: =IF($C28="","",COUNTA($C$17:$C28)) | E28: =IF($C28="","",IF(NOT(OR(M28="Completed",M28="NA",M28="Cancelled")),"S1 Schematic",IF(NOT(OR(R28="Completed",R28="NA",R28="Cancelled")),"S2 PCB Layout",IF(NOT(OR(W28="Completed",W28="NA",W28="Cancelled")),"S3 SI & PI",IF(NOT(OR(AB28="Completed",AB28="NA",AB28="Cancelled")),"S4 Bare-PCB Fab",IF(NOT(OR(AG28="Completed",AG28="NA",AG28="Cancelled")),"S5 Assembly",IF(NOT(OR(AL28="Completed",AL28="NA",AL28="Cancelled")),"S6 Bring-up",IF(NOT(OR(AQ28="Completed",AQ28="NA",AQ28="Cancelled")),"S7 BOM Procurement","All Stages Closed")))))))) | F28: =IF($C28="","",IF(COUNTIF(M28,"Cancelled")+COUNTIF(R28,"Cancelled")+COUNTIF(W28,"Cancelled")+COUNTIF(AB28,"Cancelled")+COUNTIF(AG28,"Cancelled")+COUNTIF(AL28,"Cancelled")+COUNTIF(AQ28,"Cancelled")>0,"Cancelled",IF(E28="All Stages Closed","Completed",IF(E28="S1 Schematic",M28,IF(E28="S2 PCB Layout",R28,IF(E28="S3 SI & PI",W28,IF(E28="S4 Bare-PCB Fab",AB28,IF(E28="S5 Assembly",AG28,IF(E28="S6 Bring-up",AL28,AQ28))))))))) | G28: =IF($C28="","",IF(E28="All Stages Closed","",IF(E28="S1 Schematic",IF(N28="","Not added",N28),IF(E28="S2 PCB Layout",IF(S28="","Not added",S28),IF(E28="S3 SI & PI",IF(X28="","Not added",X28),IF(E28="S4 Bare-PCB Fab",IF(AC28="","Not added",AC28),IF(E28="S5 Assembly",IF(AH28="","Not added",AH28),IF(E28="S6 Bring-up",IF(AM28="","Not added",AM28),IF(AR28="","Not added",AR28))))))))) | H28: =IF($C28="","",IF(OR(F28="Completed",F28="Cancelled"),"",IF(NOT(ISNUMBER(G28)),"No date set",IF(TODAY()>G28,TODAY()-G28&" days late",G28-TODAY()&" days left")))) | I28: =IF($C28="","",COUNTIF(M28,"Completed")+COUNTIF(R28,"Completed")+COUNTIF(W28,"Completed")+COUNTIF(AB28,"Completed")+COUNTIF(AG28,"Completed")+COUNTIF(AL28,"Completed")+COUNTIF(AQ28,"Completed")) | J28: =IF($C28="","",7-(COUNTIF(M28,"NA")+COUNTIF(R28,"NA")+COUNTIF(W28,"NA")+COUNTIF(AB28,"NA")+COUNTIF(AG28,"NA")+COUNTIF(AL28,"NA")+COUNTIF(AQ28,"NA"))) | K28: =IFERROR(I28/J28,"") | AZ28: =IF($C28="","",IF(OR(F28="Completed",F28="Cancelled"),"",IF(AND(OR(F28="On Hold",ISNUMBER(VALUE(LEFT(H28,2)))),AY28=""),"Reason not given","")))
... A266: =IF($C266="","",COUNTA($C$17:$C266)) | E266: =IF($C266="","",IF(NOT(OR(M266="Completed",M266="NA",M266="Cancelled")),"S1 Schematic",IF(NOT(OR(R266="Completed",R266="NA",R266="Cancelled")),"S2 PCB Layout",IF(NOT(OR(W266="Completed",W266="NA",W266="Cancelled")),"S3 SI & PI",IF(NOT(OR(AB266="Completed",AB266="NA",AB266="Cancelled")),"S4 Bare-PCB Fab",IF(NOT(OR(AG266="Completed",AG266="NA",AG266="Cancelled")),"S5 Assembly",IF(NOT(OR(AL266="Completed",AL266="NA",AL266="Cancelled")),"S6 Bring-up",IF(NOT(OR(AQ266="Completed",AQ266="NA",AQ266="Cancelled")),"S7 BOM Procurement","All Stages Closed")))))))) | F266: =IF($C266="","",IF(COUNTIF(M266,"Cancelled")+COUNTIF(R266,"Cancelled")+COUNTIF(W266,"Cancelled")+COUNTIF(AB266,"Cancelled")+COUNTIF(AG266,"Cancelled")+COUNTIF(AL266,"Cancelled")+COUNTIF(AQ266,"Cancelled")>0,"Cancelled",IF(E266="All Stages Closed","Completed",IF(E266="S1 Schematic",M266,IF(E266="S2 PCB Layout",R266,IF(E266="S3 SI & PI",W266,IF(E266="S4 Bare-PCB Fab",AB266,IF(E266="S5 Assembly",AG266,IF(E266="S6 Bring-up",AL266,AQ266))))))))) | G266: =IF($C266="","",IF(E266="All Stages Closed","",IF(E266="S1 Schematic",IF(N266="","Not added",N266),IF(E266="S2 PCB Layout",IF(S266="","Not added",S266),IF(E266="S3 SI & PI",IF(X266="","Not added",X266),IF(E266="S4 Bare-PCB Fab",IF(AC266="","Not added",AC266),IF(E266="S5 Assembly",IF(AH266="","Not added",AH266),IF(E266="S6 Bring-up",IF(AM266="","Not added",AM266),IF(AR266="","Not added",AR266))))))))) | H266: =IF($C266="","",IF(OR(F266="Completed",F266="Cancelled"),"",IF(NOT(ISNUMBER(G266)),"No date set",IF(TODAY()>G266,TODAY()-G266&" days late",G266-TODAY()&" days left")))) | I266: =IF($C266="","",COUNTIF(M266,"Completed")+COUNTIF(R266,"Completed")+COUNTIF(W266,"Completed")+COUNTIF(AB266,"Completed")+COUNTIF(AG266,"Completed")+COUNTIF(AL266,"Completed")+COUNTIF(AQ266,"Completed")) | J266: =IF($C266="","",7-(COUNTIF(M266,"NA")+COUNTIF(R266,"NA")+COUNTIF(W266,"NA")+COUNTIF(AB266,"NA")+COUNTIF(AG266,"NA")+COUNTIF(AL266,"NA")+COUNTIF(AQ266,"NA"))) | K266: =IFERROR(I266/J266,"") | AZ266: =IF($C266="","",IF(OR(F266="Completed",F266="Cancelled"),"",IF(AND(OR(F266="On Hold",ISNUMBER(VALUE(LEFT(H266,2)))),AY266=""),"Reason not given","")))

Sheet COMPLETED
A1: COMPLETED BOARDS
A2: Boards where every stage is Completed or NA. You can leave this empty — the dashboard moves boards here as they close. Set Respin Needed? = Yes with a Re-entry Stage to send one back.
A4: PROJECT | E4: PROCESS ROLL-UP | L4: S1 SCHEMATIC | Q4: S2 PCB LAYOUT | V4: S3 SI & PI | AA4: S4 BARE-PCB FAB | AF4: S5 ASSEMBLY | AK4: S6 BRING-UP | AP4: S7 BOM PROCUREMENT | AU4: RESPIN CONTROL | BA4: FOLLOW-UP
A5: S.No | B5: Customer | C5: Project / Board | D5: Project Manager | E5: Current Stage | F5: Overall Status | G5: EDC (current stage) | H5: Days | I5: Stages Done | J5: Stages In Scope | K5: % Complete | L5: Owner | M5: Status | N5: EDC | O5: EDA | P5: Comment | Q5: Owner | R5: Status | S5: EDC | T5: EDA | U5: Comment | V5: Owner | W5: Status | X5: EDC | Y5: EDA | Z5: Comment | AA5: Fabricator | AB5: Status | AC5: EDC | AD5: EDA | AE5: Comment | AF5: Owner | AG5: Status | AH5: EDC | AI5: EDA | AJ5: Comment | AK5: Owner | AL5: Status | AM5: EDC | AN5: EDA | AO5: Comment | AP5: Owner | AQ5: Status | AR5: EDC | AS5: EDA | AT5: Comment | AU5: Respin Needed? | AV5: Re-entry Stage | AW5: Respin Reason | AX5: Raised On | AY5: ACTION | AZ5: # | BA5: Hold / delay reason | BB5: Reason check | BC5: Notes / Data Check
A6: =IF($C6="","",COUNTA($C$6:$C6)) | E6: =IF($C6="","",IF(NOT(OR(M6="Completed",M6="NA",M6="Cancelled")),"S1 Schematic",IF(NOT(OR(R6="Completed",R6="NA",R6="Cancelled")),"S2 PCB Layout",IF(NOT(OR(W6="Completed",W6="NA",W6="Cancelled")),"S3 SI & PI",IF(NOT(OR(AB6="Completed",AB6="NA",AB6="Cancelled")),"S4 Bare-PCB Fab",IF(NOT(OR(AG6="Completed",AG6="NA",AG6="Cancelled")),"S5 Assembly",IF(NOT(OR(AL6="Completed",AL6="NA",AL6="Cancelled")),"S6 Bring-up",IF(NOT(OR(AQ6="Completed",AQ6="NA",AQ6="Cancelled")),"S7 BOM Procurement","All Stages Closed")))))))) | F6: =IF($C6="","",IF(COUNTIF(M6,"Cancelled")+COUNTIF(R6,"Cancelled")+COUNTIF(W6,"Cancelled")+COUNTIF(AB6,"Cancelled")+COUNTIF(AG6,"Cancelled")+COUNTIF(AL6,"Cancelled")+COUNTIF(AQ6,"Cancelled")>0,"Cancelled",IF(E6="All Stages Closed","Completed",IF(E6="S1 Schematic",M6,IF(E6="S2 PCB Layout",R6,IF(E6="S3 SI & PI",W6,IF(E6="S4 Bare-PCB Fab",AB6,IF(E6="S5 Assembly",AG6,IF(E6="S6 Bring-up",AL6,AQ6))))))))) | G6: =IF($C6="","",IF(E6="All Stages Closed","",IF(E6="S1 Schematic",IF(N6="","Not added",N6),IF(E6="S2 PCB Layout",IF(S6="","Not added",S6),IF(E6="S3 SI & PI",IF(X6="","Not added",X6),IF(E6="S4 Bare-PCB Fab",IF(AC6="","Not added",AC6),IF(E6="S5 Assembly",IF(AH6="","Not added",AH6),IF(E6="S6 Bring-up",IF(AM6="","Not added",AM6),IF(AR6="","Not added",AR6))))))))) | H6: =IF($C6="","",IF(OR(F6="Completed",F6="Cancelled"),"",IF(NOT(ISNUMBER(G6)),"No date set",IF(TODAY()>G6,TODAY()-G6&" days late",G6-TODAY()&" days left")))) | I6: =IF($C6="","",COUNTIF(M6,"Completed")+COUNTIF(R6,"Completed")+COUNTIF(W6,"Completed")+COUNTIF(AB6,"Completed")+COUNTIF(AG6,"Completed")+COUNTIF(AL6,"Completed")+COUNTIF(AQ6,"Completed")) | J6: =IF($C6="","",7-(COUNTIF(M6,"NA")+COUNTIF(R6,"NA")+COUNTIF(W6,"NA")+COUNTIF(AB6,"NA")+COUNTIF(AG6,"NA")+COUNTIF(AL6,"NA")+COUNTIF(AQ6,"NA"))) | K6: =IFERROR(I6/J6,"") | AY6: =IF(AU6<>"Yes","",IF(AV6="","SELECT RE-ENTRY STAGE","MOVE TO ACTIVE at "&AV6)) | AZ6: =IF(AU6="Yes",COUNTIF($AU$6:AU6,"Yes"),"") | BB6: =IF($C6="","",IF(OR(F6="Completed",F6="Cancelled"),"",IF(AND(OR(F6="On Hold",ISNUMBER(VALUE(LEFT(H6,2)))),BA6=""),"Reason not given","")))
A7: =IF($C7="","",COUNTA($C$6:$C7)) | E7: =IF($C7="","",IF(NOT(OR(M7="Completed",M7="NA",M7="Cancelled")),"S1 Schematic",IF(NOT(OR(R7="Completed",R7="NA",R7="Cancelled")),"S2 PCB Layout",IF(NOT(OR(W7="Completed",W7="NA",W7="Cancelled")),"S3 SI & PI",IF(NOT(OR(AB7="Completed",AB7="NA",AB7="Cancelled")),"S4 Bare-PCB Fab",IF(NOT(OR(AG7="Completed",AG7="NA",AG7="Cancelled")),"S5 Assembly",IF(NOT(OR(AL7="Completed",AL7="NA",AL7="Cancelled")),"S6 Bring-up",IF(NOT(OR(AQ7="Completed",AQ7="NA",AQ7="Cancelled")),"S7 BOM Procurement","All Stages Closed")))))))) | F7: =IF($C7="","",IF(COUNTIF(M7,"Cancelled")+COUNTIF(R7,"Cancelled")+COUNTIF(W7,"Cancelled")+COUNTIF(AB7,"Cancelled")+COUNTIF(AG7,"Cancelled")+COUNTIF(AL7,"Cancelled")+COUNTIF(AQ7,"Cancelled")>0,"Cancelled",IF(E7="All Stages Closed","Completed",IF(E7="S1 Schematic",M7,IF(E7="S2 PCB Layout",R7,IF(E7="S3 SI & PI",W7,IF(E7="S4 Bare-PCB Fab",AB7,IF(E7="S5 Assembly",AG7,IF(E7="S6 Bring-up",AL7,AQ7))))))))) | G7: =IF($C7="","",IF(E7="All Stages Closed","",IF(E7="S1 Schematic",IF(N7="","Not added",N7),IF(E7="S2 PCB Layout",IF(S7="","Not added",S7),IF(E7="S3 SI & PI",IF(X7="","Not added",X7),IF(E7="S4 Bare-PCB Fab",IF(AC7="","Not added",AC7),IF(E7="S5 Assembly",IF(AH7="","Not added",AH7),IF(E7="S6 Bring-up",IF(AM7="","Not added",AM7),IF(AR7="","Not added",AR7))))))))) | H7: =IF($C7="","",IF(OR(F7="Completed",F7="Cancelled"),"",IF(NOT(ISNUMBER(G7)),"No date set",IF(TODAY()>G7,TODAY()-G7&" days late",G7-TODAY()&" days left")))) | I7: =IF($C7="","",COUNTIF(M7,"Completed")+COUNTIF(R7,"Completed")+COUNTIF(W7,"Completed")+COUNTIF(AB7,"Completed")+COUNTIF(AG7,"Completed")+COUNTIF(AL7,"Completed")+COUNTIF(AQ7,"Completed")) | J7: =IF($C7="","",7-(COUNTIF(M7,"NA")+COUNTIF(R7,"NA")+COUNTIF(W7,"NA")+COUNTIF(AB7,"NA")+COUNTIF(AG7,"NA")+COUNTIF(AL7,"NA")+COUNTIF(AQ7,"NA"))) | K7: =IFERROR(I7/J7,"") | AY7: =IF(AU7<>"Yes","",IF(AV7="","SELECT RE-ENTRY STAGE","MOVE TO ACTIVE at "&AV7)) | AZ7: =IF(AU7="Yes",COUNTIF($AU$6:AU7,"Yes"),"") | BB7: =IF($C7="","",IF(OR(F7="Completed",F7="Cancelled"),"",IF(AND(OR(F7="On Hold",ISNUMBER(VALUE(LEFT(H7,2)))),BA7=""),"Reason not given","")))
A8: =IF($C8="","",COUNTA($C$6:$C8)) | E8: =IF($C8="","",IF(NOT(OR(M8="Completed",M8="NA",M8="Cancelled")),"S1 Schematic",IF(NOT(OR(R8="Completed",R8="NA",R8="Cancelled")),"S2 PCB Layout",IF(NOT(OR(W8="Completed",W8="NA",W8="Cancelled")),"S3 SI & PI",IF(NOT(OR(AB8="Completed",AB8="NA",AB8="Cancelled")),"S4 Bare-PCB Fab",IF(NOT(OR(AG8="Completed",AG8="NA",AG8="Cancelled")),"S5 Assembly",IF(NOT(OR(AL8="Completed",AL8="NA",AL8="Cancelled")),"S6 Bring-up",IF(NOT(OR(AQ8="Completed",AQ8="NA",AQ8="Cancelled")),"S7 BOM Procurement","All Stages Closed")))))))) | F8: =IF($C8="","",IF(COUNTIF(M8,"Cancelled")+COUNTIF(R8,"Cancelled")+COUNTIF(W8,"Cancelled")+COUNTIF(AB8,"Cancelled")+COUNTIF(AG8,"Cancelled")+COUNTIF(AL8,"Cancelled")+COUNTIF(AQ8,"Cancelled")>0,"Cancelled",IF(E8="All Stages Closed","Completed",IF(E8="S1 Schematic",M8,IF(E8="S2 PCB Layout",R8,IF(E8="S3 SI & PI",W8,IF(E8="S4 Bare-PCB Fab",AB8,IF(E8="S5 Assembly",AG8,IF(E8="S6 Bring-up",AL8,AQ8))))))))) | G8: =IF($C8="","",IF(E8="All Stages Closed","",IF(E8="S1 Schematic",IF(N8="","Not added",N8),IF(E8="S2 PCB Layout",IF(S8="","Not added",S8),IF(E8="S3 SI & PI",IF(X8="","Not added",X8),IF(E8="S4 Bare-PCB Fab",IF(AC8="","Not added",AC8),IF(E8="S5 Assembly",IF(AH8="","Not added",AH8),IF(E8="S6 Bring-up",IF(AM8="","Not added",AM8),IF(AR8="","Not added",AR8))))))))) | H8: =IF($C8="","",IF(OR(F8="Completed",F8="Cancelled"),"",IF(NOT(ISNUMBER(G8)),"No date set",IF(TODAY()>G8,TODAY()-G8&" days late",G8-TODAY()&" days left")))) | I8: =IF($C8="","",COUNTIF(M8,"Completed")+COUNTIF(R8,"Completed")+COUNTIF(W8,"Completed")+COUNTIF(AB8,"Completed")+COUNTIF(AG8,"Completed")+COUNTIF(AL8,"Completed")+COUNTIF(AQ8,"Completed")) | J8: =IF($C8="","",7-(COUNTIF(M8,"NA")+COUNTIF(R8,"NA")+COUNTIF(W8,"NA")+COUNTIF(AB8,"NA")+COUNTIF(AG8,"NA")+COUNTIF(AL8,"NA")+COUNTIF(AQ8,"NA"))) | K8: =IFERROR(I8/J8,"") | AY8: =IF(AU8<>"Yes","",IF(AV8="","SELECT RE-ENTRY STAGE","MOVE TO ACTIVE at "&AV8)) | AZ8: =IF(AU8="Yes",COUNTIF($AU$6:AU8,"Yes"),"") | BB8: =IF($C8="","",IF(OR(F8="Completed",F8="Cancelled"),"",IF(AND(OR(F8="On Hold",ISNUMBER(VALUE(LEFT(H8,2)))),BA8=""),"Reason not given","")))
A9: =IF($C9="","",COUNTA($C$6:$C9)) | E9: =IF($C9="","",IF(NOT(OR(M9="Completed",M9="NA",M9="Cancelled")),"S1 Schematic",IF(NOT(OR(R9="Completed",R9="NA",R9="Cancelled")),"S2 PCB Layout",IF(NOT(OR(W9="Completed",W9="NA",W9="Cancelled")),"S3 SI & PI",IF(NOT(OR(AB9="Completed",AB9="NA",AB9="Cancelled")),"S4 Bare-PCB Fab",IF(NOT(OR(AG9="Completed",AG9="NA",AG9="Cancelled")),"S5 Assembly",IF(NOT(OR(AL9="Completed",AL9="NA",AL9="Cancelled")),"S6 Bring-up",IF(NOT(OR(AQ9="Completed",AQ9="NA",AQ9="Cancelled")),"S7 BOM Procurement","All Stages Closed")))))))) | F9: =IF($C9="","",IF(COUNTIF(M9,"Cancelled")+COUNTIF(R9,"Cancelled")+COUNTIF(W9,"Cancelled")+COUNTIF(AB9,"Cancelled")+COUNTIF(AG9,"Cancelled")+COUNTIF(AL9,"Cancelled")+COUNTIF(AQ9,"Cancelled")>0,"Cancelled",IF(E9="All Stages Closed","Completed",IF(E9="S1 Schematic",M9,IF(E9="S2 PCB Layout",R9,IF(E9="S3 SI & PI",W9,IF(E9="S4 Bare-PCB Fab",AB9,IF(E9="S5 Assembly",AG9,IF(E9="S6 Bring-up",AL9,AQ9))))))))) | G9: =IF($C9="","",IF(E9="All Stages Closed","",IF(E9="S1 Schematic",IF(N9="","Not added",N9),IF(E9="S2 PCB Layout",IF(S9="","Not added",S9),IF(E9="S3 SI & PI",IF(X9="","Not added",X9),IF(E9="S4 Bare-PCB Fab",IF(AC9="","Not added",AC9),IF(E9="S5 Assembly",IF(AH9="","Not added",AH9),IF(E9="S6 Bring-up",IF(AM9="","Not added",AM9),IF(AR9="","Not added",AR9))))))))) | H9: =IF($C9="","",IF(OR(F9="Completed",F9="Cancelled"),"",IF(NOT(ISNUMBER(G9)),"No date set",IF(TODAY()>G9,TODAY()-G9&" days late",G9-TODAY()&" days left")))) | I9: =IF($C9="","",COUNTIF(M9,"Completed")+COUNTIF(R9,"Completed")+COUNTIF(W9,"Completed")+COUNTIF(AB9,"Completed")+COUNTIF(AG9,"Completed")+COUNTIF(AL9,"Completed")+COUNTIF(AQ9,"Completed")) | J9: =IF($C9="","",7-(COUNTIF(M9,"NA")+COUNTIF(R9,"NA")+COUNTIF(W9,"NA")+COUNTIF(AB9,"NA")+COUNTIF(AG9,"NA")+COUNTIF(AL9,"NA")+COUNTIF(AQ9,"NA"))) | K9: =IFERROR(I9/J9,"") | AY9: =IF(AU9<>"Yes","",IF(AV9="","SELECT RE-ENTRY STAGE","MOVE TO ACTIVE at "&AV9)) | AZ9: =IF(AU9="Yes",COUNTIF($AU$6:AU9,"Yes"),"") | BB9: =IF($C9="","",IF(OR(F9="Completed",F9="Cancelled"),"",IF(AND(OR(F9="On Hold",ISNUMBER(VALUE(LEFT(H9,2)))),BA9=""),"Reason not given","")))
A10: =IF($C10="","",COUNTA($C$6:$C10)) | E10: =IF($C10="","",IF(NOT(OR(M10="Completed",M10="NA",M10="Cancelled")),"S1 Schematic",IF(NOT(OR(R10="Completed",R10="NA",R10="Cancelled")),"S2 PCB Layout",IF(NOT(OR(W10="Completed",W10="NA",W10="Cancelled")),"S3 SI & PI",IF(NOT(OR(AB10="Completed",AB10="NA",AB10="Cancelled")),"S4 Bare-PCB Fab",IF(NOT(OR(AG10="Completed",AG10="NA",AG10="Cancelled")),"S5 Assembly",IF(NOT(OR(AL10="Completed",AL10="NA",AL10="Cancelled")),"S6 Bring-up",IF(NOT(OR(AQ10="Completed",AQ10="NA",AQ10="Cancelled")),"S7 BOM Procurement","All Stages Closed")))))))) | F10: =IF($C10="","",IF(COUNTIF(M10,"Cancelled")+COUNTIF(R10,"Cancelled")+COUNTIF(W10,"Cancelled")+COUNTIF(AB10,"Cancelled")+COUNTIF(AG10,"Cancelled")+COUNTIF(AL10,"Cancelled")+COUNTIF(AQ10,"Cancelled")>0,"Cancelled",IF(E10="All Stages Closed","Completed",IF(E10="S1 Schematic",M10,IF(E10="S2 PCB Layout",R10,IF(E10="S3 SI & PI",W10,IF(E10="S4 Bare-PCB Fab",AB10,IF(E10="S5 Assembly",AG10,IF(E10="S6 Bring-up",AL10,AQ10))))))))) | G10: =IF($C10="","",IF(E10="All Stages Closed","",IF(E10="S1 Schematic",IF(N10="","Not added",N10),IF(E10="S2 PCB Layout",IF(S10="","Not added",S10),IF(E10="S3 SI & PI",IF(X10="","Not added",X10),IF(E10="S4 Bare-PCB Fab",IF(AC10="","Not added",AC10),IF(E10="S5 Assembly",IF(AH10="","Not added",AH10),IF(E10="S6 Bring-up",IF(AM10="","Not added",AM10),IF(AR10="","Not added",AR10))))))))) | H10: =IF($C10="","",IF(OR(F10="Completed",F10="Cancelled"),"",IF(NOT(ISNUMBER(G10)),"No date set",IF(TODAY()>G10,TODAY()-G10&" days late",G10-TODAY()&" days left")))) | I10: =IF($C10="","",COUNTIF(M10,"Completed")+COUNTIF(R10,"Completed")+COUNTIF(W10,"Completed")+COUNTIF(AB10,"Completed")+COUNTIF(AG10,"Completed")+COUNTIF(AL10,"Completed")+COUNTIF(AQ10,"Completed")) | J10: =IF($C10="","",7-(COUNTIF(M10,"NA")+COUNTIF(R10,"NA")+COUNTIF(W10,"NA")+COUNTIF(AB10,"NA")+COUNTIF(AG10,"NA")+COUNTIF(AL10,"NA")+COUNTIF(AQ10,"NA"))) | K10: =IFERROR(I10/J10,"") | AY10: =IF(AU10<>"Yes","",IF(AV10="","SELECT RE-ENTRY STAGE","MOVE TO ACTIVE at "&AV10)) | AZ10: =IF(AU10="Yes",COUNTIF($AU$6:AU10,"Yes"),"") | BB10: =IF($C10="","",IF(OR(F10="Completed",F10="Cancelled"),"",IF(AND(OR(F10="On Hold",ISNUMBER(VALUE(LEFT(H10,2)))),BA10=""),"Reason not given","")))
A11: =IF($C11="","",COUNTA($C$6:$C11)) | E11: =IF($C11="","",IF(NOT(OR(M11="Completed",M11="NA",M11="Cancelled")),"S1 Schematic",IF(NOT(OR(R11="Completed",R11="NA",R11="Cancelled")),"S2 PCB Layout",IF(NOT(OR(W11="Completed",W11="NA",W11="Cancelled")),"S3 SI & PI",IF(NOT(OR(AB11="Completed",AB11="NA",AB11="Cancelled")),"S4 Bare-PCB Fab",IF(NOT(OR(AG11="Completed",AG11="NA",AG11="Cancelled")),"S5 Assembly",IF(NOT(OR(AL11="Completed",AL11="NA",AL11="Cancelled")),"S6 Bring-up",IF(NOT(OR(AQ11="Completed",AQ11="NA",AQ11="Cancelled")),"S7 BOM Procurement","All Stages Closed")))))))) | F11: =IF($C11="","",IF(COUNTIF(M11,"Cancelled")+COUNTIF(R11,"Cancelled")+COUNTIF(W11,"Cancelled")+COUNTIF(AB11,"Cancelled")+COUNTIF(AG11,"Cancelled")+COUNTIF(AL11,"Cancelled")+COUNTIF(AQ11,"Cancelled")>0,"Cancelled",IF(E11="All Stages Closed","Completed",IF(E11="S1 Schematic",M11,IF(E11="S2 PCB Layout",R11,IF(E11="S3 SI & PI",W11,IF(E11="S4 Bare-PCB Fab",AB11,IF(E11="S5 Assembly",AG11,IF(E11="S6 Bring-up",AL11,AQ11))))))))) | G11: =IF($C11="","",IF(E11="All Stages Closed","",IF(E11="S1 Schematic",IF(N11="","Not added",N11),IF(E11="S2 PCB Layout",IF(S11="","Not added",S11),IF(E11="S3 SI & PI",IF(X11="","Not added",X11),IF(E11="S4 Bare-PCB Fab",IF(AC11="","Not added",AC11),IF(E11="S5 Assembly",IF(AH11="","Not added",AH11),IF(E11="S6 Bring-up",IF(AM11="","Not added",AM11),IF(AR11="","Not added",AR11))))))))) | H11: =IF($C11="","",IF(OR(F11="Completed",F11="Cancelled"),"",IF(NOT(ISNUMBER(G11)),"No date set",IF(TODAY()>G11,TODAY()-G11&" days late",G11-TODAY()&" days left")))) | I11: =IF($C11="","",COUNTIF(M11,"Completed")+COUNTIF(R11,"Completed")+COUNTIF(W11,"Completed")+COUNTIF(AB11,"Completed")+COUNTIF(AG11,"Completed")+COUNTIF(AL11,"Completed")+COUNTIF(AQ11,"Completed")) | J11: =IF($C11="","",7-(COUNTIF(M11,"NA")+COUNTIF(R11,"NA")+COUNTIF(W11,"NA")+COUNTIF(AB11,"NA")+COUNTIF(AG11,"NA")+COUNTIF(AL11,"NA")+COUNTIF(AQ11,"NA"))) | K11: =IFERROR(I11/J11,"") | AY11: =IF(AU11<>"Yes","",IF(AV11="","SELECT RE-ENTRY STAGE","MOVE TO ACTIVE at "&AV11)) | AZ11: =IF(AU11="Yes",COUNTIF($AU$6:AU11,"Yes"),"") | BB11: =IF($C11="","",IF(OR(F11="Completed",F11="Cancelled"),"",IF(AND(OR(F11="On Hold",ISNUMBER(VALUE(LEFT(H11,2)))),BA11=""),"Reason not given","")))
A12: =IF($C12="","",COUNTA($C$6:$C12)) | E12: =IF($C12="","",IF(NOT(OR(M12="Completed",M12="NA",M12="Cancelled")),"S1 Schematic",IF(NOT(OR(R12="Completed",R12="NA",R12="Cancelled")),"S2 PCB Layout",IF(NOT(OR(W12="Completed",W12="NA",W12="Cancelled")),"S3 SI & PI",IF(NOT(OR(AB12="Completed",AB12="NA",AB12="Cancelled")),"S4 Bare-PCB Fab",IF(NOT(OR(AG12="Completed",AG12="NA",AG12="Cancelled")),"S5 Assembly",IF(NOT(OR(AL12="Completed",AL12="NA",AL12="Cancelled")),"S6 Bring-up",IF(NOT(OR(AQ12="Completed",AQ12="NA",AQ12="Cancelled")),"S7 BOM Procurement","All Stages Closed")))))))) | F12: =IF($C12="","",IF(COUNTIF(M12,"Cancelled")+COUNTIF(R12,"Cancelled")+COUNTIF(W12,"Cancelled")+COUNTIF(AB12,"Cancelled")+COUNTIF(AG12,"Cancelled")+COUNTIF(AL12,"Cancelled")+COUNTIF(AQ12,"Cancelled")>0,"Cancelled",IF(E12="All Stages Closed","Completed",IF(E12="S1 Schematic",M12,IF(E12="S2 PCB Layout",R12,IF(E12="S3 SI & PI",W12,IF(E12="S4 Bare-PCB Fab",AB12,IF(E12="S5 Assembly",AG12,IF(E12="S6 Bring-up",AL12,AQ12))))))))) | G12: =IF($C12="","",IF(E12="All Stages Closed","",IF(E12="S1 Schematic",IF(N12="","Not added",N12),IF(E12="S2 PCB Layout",IF(S12="","Not added",S12),IF(E12="S3 SI & PI",IF(X12="","Not added",X12),IF(E12="S4 Bare-PCB Fab",IF(AC12="","Not added",AC12),IF(E12="S5 Assembly",IF(AH12="","Not added",AH12),IF(E12="S6 Bring-up",IF(AM12="","Not added",AM12),IF(AR12="","Not added",AR12))))))))) | H12: =IF($C12="","",IF(OR(F12="Completed",F12="Cancelled"),"",IF(NOT(ISNUMBER(G12)),"No date set",IF(TODAY()>G12,TODAY()-G12&" days late",G12-TODAY()&" days left")))) | I12: =IF($C12="","",COUNTIF(M12,"Completed")+COUNTIF(R12,"Completed")+COUNTIF(W12,"Completed")+COUNTIF(AB12,"Completed")+COUNTIF(AG12,"Completed")+COUNTIF(AL12,"Completed")+COUNTIF(AQ12,"Completed")) | J12: =IF($C12="","",7-(COUNTIF(M12,"NA")+COUNTIF(R12,"NA")+COUNTIF(W12,"NA")+COUNTIF(AB12,"NA")+COUNTIF(AG12,"NA")+COUNTIF(AL12,"NA")+COUNTIF(AQ12,"NA"))) | K12: =IFERROR(I12/J12,"") | AY12: =IF(AU12<>"Yes","",IF(AV12="","SELECT RE-ENTRY STAGE","MOVE TO ACTIVE at "&AV12)) | AZ12: =IF(AU12="Yes",COUNTIF($AU$6:AU12,"Yes"),"") | BB12: =IF($C12="","",IF(OR(F12="Completed",F12="Cancelled"),"",IF(AND(OR(F12="On Hold",ISNUMBER(VALUE(LEFT(H12,2)))),BA12=""),"Reason not given","")))
A13: =IF($C13="","",COUNTA($C$6:$C13)) | E13: =IF($C13="","",IF(NOT(OR(M13="Completed",M13="NA",M13="Cancelled")),"S1 Schematic",IF(NOT(OR(R13="Completed",R13="NA",R13="Cancelled")),"S2 PCB Layout",IF(NOT(OR(W13="Completed",W13="NA",W13="Cancelled")),"S3 SI & PI",IF(NOT(OR(AB13="Completed",AB13="NA",AB13="Cancelled")),"S4 Bare-PCB Fab",IF(NOT(OR(AG13="Completed",AG13="NA",AG13="Cancelled")),"S5 Assembly",IF(NOT(OR(AL13="Completed",AL13="NA",AL13="Cancelled")),"S6 Bring-up",IF(NOT(OR(AQ13="Completed",AQ13="NA",AQ13="Cancelled")),"S7 BOM Procurement","All Stages Closed")))))))) | F13: =IF($C13="","",IF(COUNTIF(M13,"Cancelled")+COUNTIF(R13,"Cancelled")+COUNTIF(W13,"Cancelled")+COUNTIF(AB13,"Cancelled")+COUNTIF(AG13,"Cancelled")+COUNTIF(AL13,"Cancelled")+COUNTIF(AQ13,"Cancelled")>0,"Cancelled",IF(E13="All Stages Closed","Completed",IF(E13="S1 Schematic",M13,IF(E13="S2 PCB Layout",R13,IF(E13="S3 SI & PI",W13,IF(E13="S4 Bare-PCB Fab",AB13,IF(E13="S5 Assembly",AG13,IF(E13="S6 Bring-up",AL13,AQ13))))))))) | G13: =IF($C13="","",IF(E13="All Stages Closed","",IF(E13="S1 Schematic",IF(N13="","Not added",N13),IF(E13="S2 PCB Layout",IF(S13="","Not added",S13),IF(E13="S3 SI & PI",IF(X13="","Not added",X13),IF(E13="S4 Bare-PCB Fab",IF(AC13="","Not added",AC13),IF(E13="S5 Assembly",IF(AH13="","Not added",AH13),IF(E13="S6 Bring-up",IF(AM13="","Not added",AM13),IF(AR13="","Not added",AR13))))))))) | H13: =IF($C13="","",IF(OR(F13="Completed",F13="Cancelled"),"",IF(NOT(ISNUMBER(G13)),"No date set",IF(TODAY()>G13,TODAY()-G13&" days late",G13-TODAY()&" days left")))) | I13: =IF($C13="","",COUNTIF(M13,"Completed")+COUNTIF(R13,"Completed")+COUNTIF(W13,"Completed")+COUNTIF(AB13,"Completed")+COUNTIF(AG13,"Completed")+COUNTIF(AL13,"Completed")+COUNTIF(AQ13,"Completed")) | J13: =IF($C13="","",7-(COUNTIF(M13,"NA")+COUNTIF(R13,"NA")+COUNTIF(W13,"NA")+COUNTIF(AB13,"NA")+COUNTIF(AG13,"NA")+COUNTIF(AL13,"NA")+COUNTIF(AQ13,"NA"))) | K13: =IFERROR(I13/J13,"") | AY13: =IF(AU13<>"Yes","",IF(AV13="","SELECT RE-ENTRY STAGE","MOVE TO ACTIVE at "&AV13)) | AZ13: =IF(AU13="Yes",COUNTIF($AU$6:AU13,"Yes"),"") | BB13: =IF($C13="","",IF(OR(F13="Completed",F13="Cancelled"),"",IF(AND(OR(F13="On Hold",ISNUMBER(VALUE(LEFT(H13,2)))),BA13=""),"Reason not given","")))
A14: =IF($C14="","",COUNTA($C$6:$C14)) | E14: =IF($C14="","",IF(NOT(OR(M14="Completed",M14="NA",M14="Cancelled")),"S1 Schematic",IF(NOT(OR(R14="Completed",R14="NA",R14="Cancelled")),"S2 PCB Layout",IF(NOT(OR(W14="Completed",W14="NA",W14="Cancelled")),"S3 SI & PI",IF(NOT(OR(AB14="Completed",AB14="NA",AB14="Cancelled")),"S4 Bare-PCB Fab",IF(NOT(OR(AG14="Completed",AG14="NA",AG14="Cancelled")),"S5 Assembly",IF(NOT(OR(AL14="Completed",AL14="NA",AL14="Cancelled")),"S6 Bring-up",IF(NOT(OR(AQ14="Completed",AQ14="NA",AQ14="Cancelled")),"S7 BOM Procurement","All Stages Closed")))))))) | F14: =IF($C14="","",IF(COUNTIF(M14,"Cancelled")+COUNTIF(R14,"Cancelled")+COUNTIF(W14,"Cancelled")+COUNTIF(AB14,"Cancelled")+COUNTIF(AG14,"Cancelled")+COUNTIF(AL14,"Cancelled")+COUNTIF(AQ14,"Cancelled")>0,"Cancelled",IF(E14="All Stages Closed","Completed",IF(E14="S1 Schematic",M14,IF(E14="S2 PCB Layout",R14,IF(E14="S3 SI & PI",W14,IF(E14="S4 Bare-PCB Fab",AB14,IF(E14="S5 Assembly",AG14,IF(E14="S6 Bring-up",AL14,AQ14))))))))) | G14: =IF($C14="","",IF(E14="All Stages Closed","",IF(E14="S1 Schematic",IF(N14="","Not added",N14),IF(E14="S2 PCB Layout",IF(S14="","Not added",S14),IF(E14="S3 SI & PI",IF(X14="","Not added",X14),IF(E14="S4 Bare-PCB Fab",IF(AC14="","Not added",AC14),IF(E14="S5 Assembly",IF(AH14="","Not added",AH14),IF(E14="S6 Bring-up",IF(AM14="","Not added",AM14),IF(AR14="","Not added",AR14))))))))) | H14: =IF($C14="","",IF(OR(F14="Completed",F14="Cancelled"),"",IF(NOT(ISNUMBER(G14)),"No date set",IF(TODAY()>G14,TODAY()-G14&" days late",G14-TODAY()&" days left")))) | I14: =IF($C14="","",COUNTIF(M14,"Completed")+COUNTIF(R14,"Completed")+COUNTIF(W14,"Completed")+COUNTIF(AB14,"Completed")+COUNTIF(AG14,"Completed")+COUNTIF(AL14,"Completed")+COUNTIF(AQ14,"Completed")) | J14: =IF($C14="","",7-(COUNTIF(M14,"NA")+COUNTIF(R14,"NA")+COUNTIF(W14,"NA")+COUNTIF(AB14,"NA")+COUNTIF(AG14,"NA")+COUNTIF(AL14,"NA")+COUNTIF(AQ14,"NA"))) | K14: =IFERROR(I14/J14,"") | AY14: =IF(AU14<>"Yes","",IF(AV14="","SELECT RE-ENTRY STAGE","MOVE TO ACTIVE at "&AV14)) | AZ14: =IF(AU14="Yes",COUNTIF($AU$6:AU14,"Yes"),"") | BB14: =IF($C14="","",IF(OR(F14="Completed",F14="Cancelled"),"",IF(AND(OR(F14="On Hold",ISNUMBER(VALUE(LEFT(H14,2)))),BA14=""),"Reason not given","")))
