Workbook

Sheet PROCESS DEFINITION
B2: PCB Tracker — backend data model
B3: Seven stages, four columns each: Owner, Status, EDC, EDA. The dashboard reads and writes these sheets directly.
B5: Stage | C5: Stage name | D5: What happens | E5: Completed when | F5: Owner column holds
B6: S1 | C6: Schematic Design | D6: Requirement capture, part selection, power budget, circuit capture and review. | E6: Schematic released and netlist handed to layout. | F6: A design engineer
B7: S2 | C7: PCB Layout / Design | D7: Stack-up, placement, routing, DFM checks and Gerber release. | E7: DRC/DFM clean and Gerber released. | F7: A layout engineer
B8: S3 | C8: SI & PI Simulation | D8: S-parameter extraction, DC drop, crosstalk, impedance and thermal analysis. | E8: All in-scope interfaces within margin and report shared. | F8: A simulation engineer
B9: S4 | C9: Bare-PCB Fabrication | D9: Bare board ordered and tracked to receipt. | E9: Boards received and inspected. | F9: The fabricator, not a staff member
B10: S5 | C10: Assembly | D10: Component assembly and soldering. | E10: Board populated and inspected. | F10: A hardware engineer
B11: S6 | C11: Bring-up | D11: First power-on, functional validation and debug. | E11: Board validated and handed over. | F11: A hardware engineer
B12: S7 | C12: BOM Procurement | D12: Costing, sourcing and chasing long-lead parts. | E12: Parts sourced or alternates agreed. | F12: A design engineer
B14: Column contract the dashboard depends on
B15: - The field header row must contain a cell reading "Project / Board", with the stage group headers in the row directly above it.
B16: - Each stage group header must keep its name — SCHEMATIC, PCB LAYOUT, SI & PI, BARE-PCB FAB, ASSEMBLY, BRING-UP, BOM PROCUREMENT. The S<n> prefix is ignored, so stages can be renumbered or moved.
B17: - Within a stage block the order is Owner, Status, EDC, EDA. The dashboard detects EDA by its header, so a block without it still works.
B18: - Current Stage, Overall Status, EDC (current stage), Delay, Stages Done, Stages In Scope and % Through Process are formulas. Do not type over them.
B19: - Overall Status alone decides which sheet a board belongs on. The dashboard reads it back after every save and moves the row.
B20: - Owner values must match the "Name in sheet" column on PEOPLE, or the People tab cannot attribute the work. Two people are combined with " + ".
B22: Live roll-up
B23: Stage | C23: Completed | D23: In Progress | E23: On Hold | F23: Not Started | G23: Cancelled | H23: NA
B24: S1 Schematic | C24: =COUNTIF(COMPLETED!$M$6:$M$47,"Completed")+COUNTIF(ACTIVE!$M$17:$M$41,"Completed") -> 53 | D24: =COUNTIF(COMPLETED!$M$6:$M$47,"In Progress")+COUNTIF(ACTIVE!$M$17:$M$41,"In Progress") -> 1 | E24: =COUNTIF(COMPLETED!$M$6:$M$47,"On Hold")+COUNTIF(ACTIVE!$M$17:$M$41,"On Hold") -> 2 | F24: =COUNTIF(COMPLETED!$M$6:$M$47,"Not Started")+COUNTIF(ACTIVE!$M$17:$M$41,"Not Started") -> 4 | G24: =COUNTIF(COMPLETED!$M$6:$M$47,"Cancelled")+COUNTIF(ACTIVE!$M$17:$M$41,"Cancelled") -> 1 | H24: =COUNTIF(COMPLETED!$M$6:$M$47,"NA")+COUNTIF(ACTIVE!$M$17:$M$41,"NA") -> 6
B25: S2 PCB Layout | C25: =COUNTIF(COMPLETED!$Q$6:$Q$47,"Completed")+COUNTIF(ACTIVE!$Q$17:$Q$41,"Completed") -> 47 | D25: =COUNTIF(COMPLETED!$Q$6:$Q$47,"In Progress")+COUNTIF(ACTIVE!$Q$17:$Q$41,"In Progress") -> 5 | E25: =COUNTIF(COMPLETED!$Q$6:$Q$47,"On Hold")+COUNTIF(ACTIVE!$Q$17:$Q$41,"On Hold") -> 3 | F25: =COUNTIF(COMPLETED!$Q$6:$Q$47,"Not Started")+COUNTIF(ACTIVE!$Q$17:$Q$41,"Not Started") -> 6 | G25: =COUNTIF(COMPLETED!$Q$6:$Q$47,"Cancelled")+COUNTIF(ACTIVE!$Q$17:$Q$41,"Cancelled") -> 1 | H25: =COUNTIF(COMPLETED!$Q$6:$Q$47,"NA")+COUNTIF(ACTIVE!$Q$17:$Q$41,"NA") -> 5
B26: S3 SI & PI | C26: =COUNTIF(COMPLETED!$U$6:$U$47,"Completed")+COUNTIF(ACTIVE!$U$17:$U$41,"Completed") -> 31 | D26: =COUNTIF(COMPLETED!$U$6:$U$47,"In Progress")+COUNTIF(ACTIVE!$U$17:$U$41,"In Progress") -> 6 | E26: =COUNTIF(COMPLETED!$U$6:$U$47,"On Hold")+COUNTIF(ACTIVE!$U$17:$U$41,"On Hold") -> 4 | F26: =COUNTIF(COMPLETED!$U$6:$U$47,"Not Started")+COUNTIF(ACTIVE!$U$17:$U$41,"Not Started") -> 9 | G26: =COUNTIF(COMPLETED!$U$6:$U$47,"Cancelled")+COUNTIF(ACTIVE!$U$17:$U$41,"Cancelled") -> 1 | H26: =COUNTIF(COMPLETED!$U$6:$U$47,"NA")+COUNTIF(ACTIVE!$U$17:$U$41,"NA") -> 16
B27: S4 Bare-PCB Fab | C27: =COUNTIF(COMPLETED!$Y$6:$Y$47,"Completed")+COUNTIF(ACTIVE!$Y$17:$Y$41,"Completed") -> 36 | D27: =COUNTIF(COMPLETED!$Y$6:$Y$47,"In Progress")+COUNTIF(ACTIVE!$Y$17:$Y$41,"In Progress") -> 0 | E27: =COUNTIF(COMPLETED!$Y$6:$Y$47,"On Hold")+COUNTIF(ACTIVE!$Y$17:$Y$41,"On Hold") -> 5 | F27: =COUNTIF(COMPLETED!$Y$6:$Y$47,"Not Started")+COUNTIF(ACTIVE!$Y$17:$Y$41,"Not Started") -> 14 | G27: =COUNTIF(COMPLETED!$Y$6:$Y$47,"Cancelled")+COUNTIF(ACTIVE!$Y$17:$Y$41,"Cancelled") -> 1 | H27: =COUNTIF(COMPLETED!$Y$6:$Y$47,"NA")+COUNTIF(ACTIVE!$Y$17:$Y$41,"NA") -> 11
B28: S5 Assembly | C28: =COUNTIF(COMPLETED!$AC$6:$AC$47,"Completed")+COUNTIF(ACTIVE!$AC$17:$AC$41,"Completed") -> 32 | D28: =COUNTIF(COMPLETED!$AC$6:$AC$47,"In Progress")+COUNTIF(ACTIVE!$AC$17:$AC$41,"In Progress") -> 3 | E28: =COUNTIF(COMPLETED!$AC$6:$AC$47,"On Hold")+COUNTIF(ACTIVE!$AC$17:$AC$41,"On Hold") -> 3 | F28: =COUNTIF(COMPLETED!$AC$6:$AC$47,"Not Started")+COUNTIF(ACTIVE!$AC$17:$AC$41,"Not Started") -> 14 | G28: =COUNTIF(COMPLETED!$AC$6:$AC$47,"Cancelled")+COUNTIF(ACTIVE!$AC$17:$AC$41,"Cancelled") -> 1 | H28: =COUNTIF(COMPLETED!$AC$6:$AC$47,"NA")+COUNTIF(ACTIVE!$AC$17:$AC$41,"NA") -> 14
B29: S6 Bring-up | C29: =COUNTIF(COMPLETED!$AG$6:$AG$47,"Completed")+COUNTIF(ACTIVE!$AG$17:$AG$41,"Completed") -> 1 | D29: =COUNTIF(COMPLETED!$AG$6:$AG$47,"In Progress")+COUNTIF(ACTIVE!$AG$17:$AG$41,"In Progress") -> 1 | E29: =COUNTIF(COMPLETED!$AG$6:$AG$47,"On Hold")+COUNTIF(ACTIVE!$AG$17:$AG$41,"On Hold") -> 0 | F29: =COUNTIF(COMPLETED!$AG$6:$AG$47,"Not Started")+COUNTIF(ACTIVE!$AG$17:$AG$41,"Not Started") -> 0 | G29: =COUNTIF(COMPLETED!$AG$6:$AG$47,"Cancelled")+COUNTIF(ACTIVE!$AG$17:$AG$41,"Cancelled") -> 0 | H29: =COUNTIF(COMPLETED!$AG$6:$AG$47,"NA")+COUNTIF(ACTIVE!$AG$17:$AG$41,"NA") -> 65
B30: S7 BOM Procurement | C30: =COUNTIF(COMPLETED!$AK$6:$AK$47,"Completed")+COUNTIF(ACTIVE!$AK$17:$AK$41,"Completed") -> 1 | D30: =COUNTIF(COMPLETED!$AK$6:$AK$47,"In Progress")+COUNTIF(ACTIVE!$AK$17:$AK$41,"In Progress") -> 1 | E30: =COUNTIF(COMPLETED!$AK$6:$AK$47,"On Hold")+COUNTIF(ACTIVE!$AK$17:$AK$41,"On Hold") -> 0 | F30: =COUNTIF(COMPLETED!$AK$6:$AK$47,"Not Started")+COUNTIF(ACTIVE!$AK$17:$AK$41,"Not Started") -> 0 | G30: =COUNTIF(COMPLETED!$AK$6:$AK$47,"Cancelled")+COUNTIF(ACTIVE!$AK$17:$AK$41,"Cancelled") -> 0 | H30: =COUNTIF(COMPLETED!$AK$6:$AK$47,"NA")+COUNTIF(ACTIVE!$AK$17:$AK$41,"NA") -> 65

Sheet LISTS
A1: Status | B1: Re-entry Stage | C1: Respin Reason | D1: Yes/No | E1: Customer | F1: Hold / delay reason | G1: Owner
A2: Completed | B2: S1 Schematic | C2: Design defect found at bring-up | D2: Yes | E2: Aerx Labs | F2: Waiting on customer feedback | G2: Srinivas
A3: In Progress | B3: S2 PCB Layout | C3: Component obsolete / not sourceable | D3: No | E3: FLC | F3: Waiting on component / long-lead part | G3: Sunil
A4: On Hold | B4: S3 SI & PI | C4: Customer change request | E4: GMR | F4: De-prioritised for another board | G4: Samudra
A5: Not Started | B5: S4 Bare-PCB Fab | C5: SI / PI failure | E5: HAL | F5: Rework after SI/PI review | G5: Anji
A6: NA | B6: S5 Assembly | C6: Fabrication defect | E6: Internal | F6: Waiting on updated schematic | G6: Vivek
A7: Cancelled | B7: S6 Bring-up | C7: Assembly or footprint error | E7: Not set | F7: Fab or assembly queue | G7: Veeresh
B8: S7 BOM Procurement | C8: Performance not met | E8: Qernel.AI | F8: Owner not available | G8: Ramesh
C9: Other - see comment | E9: RCI | F9: Scope or SoW not agreed | G9: Vardhan
E10: TRS | F10: Other - see comment | G10: Keerthi
E11: Voila Tech | G11: Harika
E12: ZMD | G12: Sandhya
G13: Naveen
G14: Rajesh Sir
G15: PCB Power
G16: JLC
G17: Micropack

Sheet PEOPLE
B2: Hardware team
B3: The dashboard joins stage owners to people through the "Name in sheet" column. A stage owner cell may combine two people with a "+", and each part is matched here.
B5: Employee code | C5: Name | D5: Function | E5: Experience (yrs) | F5: Billing | G5: Projects | H5: Plan | I5: Billed in | J5: Name in sheet
C6: Srinivasa Rao Supuri | D6: Hardware | E6: 14 | F6: Billed | G6: FLC | H6: Belly Camera | I6: Belly Cam | J6: Srinivas
B7: VC_124 | C7: Galipothu Sunil Kumar | D7: Hardware | E7: 18 | F7: Billed | G7: FLC + TRS + Smart IP Camera | H7: Smart IP Camera, PVC Card | J7: Sunil
B8: VC_176 | C8: Jampani Samudralankaiah | D8: Hardware | E8: 6.4 | F8: Billed | G8: FLC + Smart IP Camera + AI Edge Server + RCI ITS | H8: Belly Camera, ZMD Edge | I8: Belly Cam, FLC | J8: Samudra
B9: VC_183 | C9: Varimadla Anjaneyulu | D9: Hardware | E9: 8.1 | F9: Billed | G9: FLC + TRS + Internal / Web + RCI ITS | H9: Support to all Projects | J9: Anji
B10: VC_224 | C10: Chintha Vivek Sai | D10: Hardware | E10: 0.1 | F10: Billed | G10: FLC + TRS + Smart IP Camera | H10: need to discuss in August | I10: Belly Cam | J10: Vivek
B11: VC_161 | C11: Veeresh Meeniga | D11: Hardware | E11: 2.7 | F11: Billed | G11: FLC + RCI ITS + RFSOC | H11: need to discuss in Nov | I11: RCI | J11: Veeresh
B12: VC_141 | C12: Ravada Ramesh | D12: Hardware | E12: 4.2 | F12: Billed | G12: TRS | H12: need to discuss in August | J12: Ramesh
B13: VC_163 | C13: Ruka Nandi Vardhan Reddy | D13: Hardware | E13: 2.7 | F13: Billed | G13: TRS + Voila Tech + AI Edge Server | H13: need to discuss in August | J13: Vardhan
B14: VC_196 | C14: Keerthi Sepana | D14: Hardware | E14: 1.3 | F14: Billed | G14: TRS + Voila Tech | H14: need to discuss in August | J14: Keerthi
B15: VC_200 | C15: Harika Kunduru | D15: Hardware | E15: 4 | F15: Billed | G15: Smart IP Camera | H15: Smart IP Camera | J15: Harika
B16: VC_229 | C16: Bommi Sandhya | D16: Hardware | J16: Sandhya
C17: Naveen | D17: Hardware | J17: Naveen
C18: Rajesh | D18: Hardware | J18: Rajesh Sir
B20: Fabrication vendors
B21: PCB Power | C21: vendor, not counted as workload
B22: JLC | C22: vendor, not counted as workload
B23: Micropack | C23: vendor, not counted as workload

Sheet COMPLETED
A1: COMPLETED BOARDS
A2: Every stage is Completed or NA. Set Respin Needed? = Yes and pick a Re-entry Stage to send a board back; the dashboard moves the row for you.
A4: PROJECT | E4: PROCESS ROLL-UP | L4: S1 SCHEMATIC | P4: S2 PCB LAYOUT | T4: S3 SI & PI | X4: S4 BARE-PCB FAB | AB4: S5 ASSEMBLY | AF4: S6 BRING-UP | AJ4: S7 BOM PROCUREMENT | AN4: RESPIN CONTROL (set these to send a board back to ACTIVE) | AT4: FOLLOW-UP
A5: S.No | B5: Customer | C5: Project / Board | D5: Project Manager | E5: Current Stage | F5: Overall Status | G5: EDC (current stage) | H5: Delay (days) | I5: Stages Done | J5: Stages In Scope | K5: % Through Process | L5: Owner | M5: Status | N5: EDC | O5: EDA | P5: Owner | Q5: Status | R5: EDC | S5: EDA | T5: Owner | U5: Status | V5: EDC | W5: EDA | X5: Fabricator | Y5: Status | Z5: EDC | AA5: EDA | AB5: Owner | AC5: Status | AD5: EDC | AE5: EDA | AF5: Owner | AG5: Status | AH5: EDC | AI5: EDA | AJ5: Owner | AK5: Status | AL5: EDC | AM5: EDA | AN5: Respin Needed? | AO5: Re-entry Stage | AP5: Respin Reason | AQ5: Raised On | AR5: ACTION | AS5: # | AT5: Hold / delay reason | AU5: Reason check | AV5: Latest Comment | AW5: Notes / Data Check
A6: 1 | B6: Aerx Labs | C6: DRVU_Mother_Board | D6: Rajesh | E6: =IF(NOT(OR(M6="Completed",M6="NA",M6="Cancelled")),"S1 Schematic",IF(NOT(OR(Q6="Completed",Q6="NA",Q6="Cancelled")),"S2 PCB Layout",IF(NOT(OR(U6="Completed",U6="NA",U6="Cancelled")),"S3 SI & PI",IF(NOT(OR(Y6="Completed",Y6="NA",Y6="Cancelled")),"S4 Bare-PCB Fab",IF(NOT(OR(AC6="Completed",AC6="NA",AC6="Cancelled")),"S5 Assembly",IF(NOT(OR(AG6="Completed",AG6="NA",AG6="Cancelled")),"S6 Bring-up",IF(NOT(OR(AK6="Completed",AK6="NA",AK6="Cancelled")),"S7 BOM Procurement","All Stages Closed"))))))) -> All Stages Closed | F6: =IF(COUNTIF(M6,"Cancelled")+COUNTIF(Q6,"Cancelled")+COUNTIF(U6,"Cancelled")+COUNTIF(Y6,"Cancelled")+COUNTIF(AC6,"Cancelled")+COUNTIF(AG6,"Cancelled")+COUNTIF(AK6,"Cancelled")>0,"Cancelled",IF(E6="All Stages Closed","Completed",IF(E6="S1 Schematic",M6,IF(E6="S2 PCB Layout",Q6,IF(E6="S3 SI & PI",U6,IF(E6="S4 Bare-PCB Fab",Y6,IF(E6="S5 Assembly",AC6,IF(E6="S6 Bring-up",AG6,AK6)))))))) -> Completed | G6: =IF(E6="All Stages Closed","",IF(E6="S1 Schematic",IF(N6="","Not added",N6),IF(E6="S2 PCB Layout",IF(R6="","Not added",R6),IF(E6="S3 SI & PI",IF(V6="","Not added",V6),IF(E6="S4 Bare-PCB Fab",IF(Z6="","Not added",Z6),IF(E6="S5 Assembly",IF(AD6="","Not added",AD6),IF(E6="S6 Bring-up",IF(AH6="","Not added",AH6),IF(AL6="","Not added",AL6)))))))) | H6: =IF(OR(F6="Completed",F6="Cancelled"),"",IF(NOT(ISNUMBER(G6)),"Date not added",IF(TODAY()>G6,TODAY()-G6,G6-TODAY()&" days left"))) | I6: =COUNTIF(M6,"Completed")+COUNTIF(Q6,"Completed")+COUNTIF(U6,"Completed")+COUNTIF(Y6,"Completed")+COUNTIF(AC6,"Completed")+COUNTIF(AG6,"Completed")+COUNTIF(AK6,"Completed") -> 1 | J6: =7-(COUNTIF(M6,"NA")+COUNTIF(Q6,"NA")+COUNTIF(U6,"NA")+COUNTIF(Y6,"NA")+COUNTIF(AC6,"NA")+COUNTIF(AG6,"NA")+COUNTIF(AK6,"NA")) -> 1 | K6: =IFERROR(I6/J6,"") -> 1 | M6: NA | Q6: NA | T6: Vivek | U6: Completed | V6: 46209 | Y6: NA | AC6: NA | AG6: NA | AK6: NA | AN6: No | AR6: =IF(AN6<>"Yes","",IF(AO6="","SELECT RE-ENTRY STAGE","MOVE TO ACTIVE at "&AO6)) | AS6: =IF(AN6="Yes",COUNTIF($AN$6:AN6,"Yes"),"") | AU6: =IF(OR(F6="Completed",F6="Cancelled"),"",IF(AND(OR(F6="On Hold",ISNUMBER(H6)),AT6=""),"Reason not given","")) | AV6: SI&PI analysis completed shared with the customer
A7: 2 | B7: Aerx Labs | C7: PVCC_Board | D7: Rajessh | E7: =IF(NOT(OR(M7="Completed",M7="NA",M7="Cancelled")),"S1 Schematic",IF(NOT(OR(Q7="Completed",Q7="NA",Q7="Cancelled")),"S2 PCB Layout",IF(NOT(OR(U7="Completed",U7="NA",U7="Cancelled")),"S3 SI & PI",IF(NOT(OR(Y7="Completed",Y7="NA",Y7="Cancelled")),"S4 Bare-PCB Fab",IF(NOT(OR(AC7="Completed",AC7="NA",AC7="Cancelled")),"S5 Assembly",IF(NOT(OR(AG7="Completed",AG7="NA",AG7="Cancelled")),"S6 Bring-up",IF(NOT(OR(AK7="Completed",AK7="NA",AK7="Cancelled")),"S7 BOM Procurement","All Stages Closed"))))))) -> All Stages Closed | F7: =IF(COUNTIF(M7,"Cancelled")+COUNTIF(Q7,"Cancelled")+COUNTIF(U7,"Cancelled")+COUNTIF(Y7,"Cancelled")+COUNTIF(AC7,"Cancelled")+COUNTIF(AG7,"Cancelled")+COUNTIF(AK7,"Cancelled")>0,"Cancelled",IF(E7="All Stages Closed","Completed",IF(E7="S1 Schematic",M7,IF(E7="S2 PCB Layout",Q7,IF(E7="S3 SI & PI",U7,IF(E7="S4 Bare-PCB Fab",Y7,IF(E7="S5 Assembly",AC7,IF(E7="S6 Bring-up",AG7,AK7)))))))) -> Completed | G7: =IF(E7="All Stages Closed","",IF(E7="S1 Schematic",IF(N7="","Not added",N7),IF(E7="S2 PCB Layout",IF(R7="","Not added",R7),IF(E7="S3 SI & PI",IF(V7="","Not added",V7),IF(E7="S4 Bare-PCB Fab",IF(Z7="","Not added",Z7),IF(E7="S5 Assembly",IF(AD7="","Not added",AD7),IF(E7="S6 Bring-up",IF(AH7="","Not added",AH7),IF(AL7="","Not added",AL7)))))))) | H7: =IF(OR(F7="Completed",F7="Cancelled"),"",IF(NOT(ISNUMBER(G7)),"Date not added",IF(TODAY()>G7,TODAY()-G7,G7-TODAY()&" days left"))) | I7: =COUNTIF(M7,"Completed")+COUNTIF(Q7,"Completed")+COUNTIF(U7,"Completed")+COUNTIF(Y7,"Completed")+COUNTIF(AC7,"Completed")+COUNTIF(AG7,"Completed")+COUNTIF(AK7,"Completed") -> 1 | J7: =7-(COUNTIF(M7,"NA")+COUNTIF(Q7,"NA")+COUNTIF(U7,"NA")+COUNTIF(Y7,"NA")+COUNTIF(AC7,"NA")+COUNTIF(AG7,"NA")+COUNTIF(AK7,"NA")) -> 1 | K7: =IFERROR(I7/J7,"") -> 1 | M7: NA | Q7: NA | T7: Vivek | U7: Completed | V7: 46213 | Y7: NA | AC7: NA | AG7: NA | AK7: NA | AN7: No | AR7: =IF(AN7<>"Yes","",IF(AO7="","SELECT RE-ENTRY STAGE","MOVE TO ACTIVE at "&AO7)) | AS7: =IF(AN7="Yes",COUNTIF($AN$6:AN7,"Yes"),"") | AU7: =IF(OR(F7="Completed",F7="Cancelled"),"",IF(AND(OR(F7="On Hold",ISNUMBER(H7)),AT7=""),"Reason not given","")) | AV7: Completed the SI & PI analysis and shared the report witht the customer
A8: 3 | B8: FLC | C8: Hardware Validation(FLC) | D8: Rajesh | E8: =IF(NOT(OR(M8="Completed",M8="NA",M8="Cancelled")),"S1 Schematic",IF(NOT(OR(Q8="Completed",Q8="NA",Q8="Cancelled")),"S2 PCB Layout",IF(NOT(OR(U8="Completed",U8="NA",U8="Cancelled")),"S3 SI & PI",IF(NOT(OR(Y8="Completed",Y8="NA",Y8="Cancelled")),"S4 Bare-PCB Fab",IF(NOT(OR(AC8="Completed",AC8="NA",AC8="Cancelled")),"S5 Assembly",IF(NOT(OR(AG8="Completed",AG8="NA",AG8="Cancelled")),"S6 Bring-up",IF(NOT(OR(AK8="Completed",AK8="NA",AK8="Cancelled")),"S7 BOM Procurement","All Stages Closed"))))))) -> All Stages Closed | F8: =IF(COUNTIF(M8,"Cancelled")+COUNTIF(Q8,"Cancelled")+COUNTIF(U8,"Cancelled")+COUNTIF(Y8,"Cancelled")+COUNTIF(AC8,"Cancelled")+COUNTIF(AG8,"Cancelled")+COUNTIF(AK8,"Cancelled")>0,"Cancelled",IF(E8="All Stages Closed","Completed",IF(E8="S1 Schematic",M8,IF(E8="S2 PCB Layout",Q8,IF(E8="S3 SI & PI",U8,IF(E8="S4 Bare-PCB Fab",Y8,IF(E8="S5 Assembly",AC8,IF(E8="S6 Bring-up",AG8,AK8)))))))) -> Completed | G8: =IF(E8="All Stages Closed","",IF(E8="S1 Schematic",IF(N8="","Not added",N8),IF(E8="S2 PCB Layout",IF(R8="","Not added",R8),IF(E8="S3 SI & PI",IF(V8="","Not added",V8),IF(E8="S4 Bare-PCB Fab",IF(Z8="","Not added",Z8),IF(E8="S5 Assembly",IF(AD8="","Not added",AD8),IF(E8="S6 Bring-up",IF(AH8="","Not added",AH8),IF(AL8="","Not added",AL8)))))))) | H8: =IF(OR(F8="Completed",F8="Cancelled"),"",IF(NOT(ISNUMBER(G8)),"Date not added",IF(TODAY()>G8,TODAY()-G8,G8-TODAY()&" days left"))) | I8: =COUNTIF(M8,"Completed")+COUNTIF(Q8,"Completed")+COUNTIF(U8,"Completed")+COUNTIF(Y8,"Completed")+COUNTIF(AC8,"Completed")+COUNTIF(AG8,"Completed")+COUNTIF(AK8,"Completed") -> 5 | J8: =7-(COUNTIF(M8,"NA")+COUNTIF(Q8,"NA")+COUNTIF(U8,"NA")+COUNTIF(Y8,"NA")+COUNTIF(AC8,"NA")+COUNTIF(AG8,"NA")+COUNTIF(AK8,"NA")) -> 5 | K8: =IFERROR(I8/J8,"") -> 1 | L8: Veeresh + Samudra | M8: Completed | P8: Veeresh + Samudra | Q8: Completed | T8: Vivek | U8: Completed | X8: Sunil | Y8: Completed | AB8: Anji | AC8: Completed | AG8: NA | AK8: NA | AN8: No | AR8: =IF(AN8<>"Yes","",IF(AO8="","SELECT RE-ENTRY STAGE","MOVE TO ACTIVE at "&AO8)) | AS8: =IF(AN8="Yes",COUNTIF($AN$6:AN8,"Yes"),"") | AU8: =IF(OR(F8="Completed",F8="Cancelled"),"",IF(AND(OR(F8="On Hold",ISNUMBER(H8)),AT8=""),"Reason not given",""))
A9: 4 | B9: FLC | C9: MKB_LITE_VALIDATION_V1 | D9: Rajesh | E9: =IF(NOT(OR(M9="Completed",M9="NA",M9="Cancelled")),"S1 Schematic",IF(NOT(OR(Q9="Completed",Q9="NA",Q9="Cancelled")),"S2 PCB Layout",IF(NOT(OR(U9="Completed",U9="NA",U9="Cancelled")),"S3 SI & PI",IF(NOT(OR(Y9="Completed",Y9="NA",Y9="Cancelled")),"S4 Bare-PCB Fab",IF(NOT(OR(AC9="Completed",AC9="NA",AC9="Cancelled")),"S5 Assembly",IF(NOT(OR(AG9="Completed",AG9="NA",AG9="Cancelled")),"S6 Bring-up",IF(NOT(OR(AK9="Completed",AK9="NA",AK9="Cancelled")),"S7 BOM Procurement","All Stages Closed"))))))) -> All Stages Closed | F9: =IF(COUNTIF(M9,"Cancelled")+COUNTIF(Q9,"Cancelled")+COUNTIF(U9,"Cancelled")+COUNTIF(Y9,"Cancelled")+COUNTIF(AC9,"Cancelled")+COUNTIF(AG9,"Cancelled")+COUNTIF(AK9,"Cancelled")>0,"Cancelled",IF(E9="All Stages Closed","Completed",IF(E9="S1 Schematic",M9,IF(E9="S2 PCB Layout",Q9,IF(E9="S3 SI & PI",U9,IF(E9="S4 Bare-PCB Fab",Y9,IF(E9="S5 Assembly",AC9,IF(E9="S6 Bring-up",AG9,AK9)))))))) -> Completed | G9: =IF(E9="All Stages Closed","",IF(E9="S1 Schematic",IF(N9="","Not added",N9),IF(E9="S2 PCB Layout",IF(R9="","Not added",R9),IF(E9="S3 SI & PI",IF(V9="","Not added",V9),IF(E9="S4 Bare-PCB Fab",IF(Z9="","Not added",Z9),IF(E9="S5 Assembly",IF(AD9="","Not added",AD9),IF(E9="S6 Bring-up",IF(AH9="","Not added",AH9),IF(AL9="","Not added",AL9)))))))) | H9: =IF(OR(F9="Completed",F9="Cancelled"),"",IF(NOT(ISNUMBER(G9)),"Date not added",IF(TODAY()>G9,TODAY()-G9,G9-TODAY()&" days left"))) | I9: =COUNTIF(M9,"Completed")+COUNTIF(Q9,"Completed")+COUNTIF(U9,"Completed")+COUNTIF(Y9,"Completed")+COUNTIF(AC9,"Completed")+COUNTIF(AG9,"Completed")+COUNTIF(AK9,"Completed") -> 5 | J9: =7-(COUNTIF(M9,"NA")+COUNTIF(Q9,"NA")+COUNTIF(U9,"NA")+COUNTIF(Y9,"NA")+COUNTIF(AC9,"NA")+COUNTIF(AG9,"NA")+COUNTIF(AK9,"NA")) -> 5 | K9: =IFERROR(I9/J9,"") -> 1 | L9: Veeresh + Samudra | M9: Completed | P9: Veeresh + Samudra | Q9: Completed | T9: Vivek | U9: Completed | X9: Sunil | Y9: Completed | AB9: Anji | AC9: Completed | AG9: NA | AK9: NA | AN9: No | AR9: =IF(AN9<>"Yes","",IF(AO9="","SELECT RE-ENTRY STAGE","MOVE TO ACTIVE at "&AO9)) | AS9: =IF(AN9="Yes",COUNTIF($AN$6:AN9,"Yes"),"") | AU9: =IF(OR(F9="Completed",F9="Cancelled"),"",IF(AND(OR(F9="On Hold",ISNUMBER(H9)),AT9=""),"Reason not given","")) | AV9: Performed the Partial SI and shared the reports. Later, after release, performed the SI & PI to find the issues for the DDR Inteface, PCIE Interface & Power Rails.
A10: 5 | B10: FLC | C10: MKB_LITE_VALIDATION_V2 | D10: Rajesh | E10: =IF(NOT(OR(M10="Completed",M10="NA",M10="Cancelled")),"S1 Schematic",IF(NOT(OR(Q10="Completed",Q10="NA",Q10="Cancelled")),"S2 PCB Layout",IF(NOT(OR(U10="Completed",U10="NA",U10="Cancelled")),"S3 SI & PI",IF(NOT(OR(Y10="Completed",Y10="NA",Y10="Cancelled")),"S4 Bare-PCB Fab",IF(NOT(OR(AC10="Completed",AC10="NA",AC10="Cancelled")),"S5 Assembly",IF(NOT(OR(AG10="Completed",AG10="NA",AG10="Cancelled")),"S6 Bring-up",IF(NOT(OR(AK10="Completed",AK10="NA",AK10="Cancelled")),"S7 BOM Procurement","All Stages Closed"))))))) -> All Stages Closed | F10: =IF(COUNTIF(M10,"Cancelled")+COUNTIF(Q10,"Cancelled")+COUNTIF(U10,"Cancelled")+COUNTIF(Y10,"Cancelled")+COUNTIF(AC10,"Cancelled")+COUNTIF(AG10,"Cancelled")+COUNTIF(AK10,"Cancelled")>0,"Cancelled",IF(E10="All Stages Closed","Completed",IF(E10="S1 Schematic",M10,IF(E10="S2 PCB Layout",Q10,IF(E10="S3 SI & PI",U10,IF(E10="S4 Bare-PCB Fab",Y10,IF(E10="S5 Assembly",AC10,IF(E10="S6 Bring-up",AG10,AK10)))))))) -> Completed | G10: =IF(E10="All Stages Closed","",IF(E10="S1 Schematic",IF(N10="","Not added",N10),IF(E10="S2 PCB Layout",IF(R10="","Not added",R10),IF(E10="S3 SI & PI",IF(V10="","Not added",V10),IF(E10="S4 Bare-PCB Fab",IF(Z10="","Not added",Z10),IF(E10="S5 Assembly",IF(AD10="","Not added",AD10),IF(E10="S6 Bring-up",IF(AH10="","Not added",AH10),IF(AL10="","Not added",AL10)))))))) | H10: =IF(OR(F10="Completed",F10="Cancelled"),"",IF(NOT(ISNUMBER(G10)),"Date not added",IF(TODAY()>G10,TODAY()-G10,G10-TODAY()&" days left"))) | I10: =COUNTIF(M10,"Completed")+COUNTIF(Q10,"Completed")+COUNTIF(U10,"Completed")+COUNTIF(Y10,"Completed")+COUNTIF(AC10,"Completed")+COUNTIF(AG10,"Completed")+COUNTIF(AK10,"Completed") -> 5 | J10: =7-(COUNTIF(M10,"NA")+COUNTIF(Q10,"NA")+COUNTIF(U10,"NA")+COUNTIF(Y10,"NA")+COUNTIF(AC10,"NA")+COUNTIF(AG10,"NA")+COUNTIF(AK10,"NA")) -> 5 | K10: =IFERROR(I10/J10,"") -> 1 | L10: Veeresh + Samudra | M10: Completed | N10: 46149 | P10: Veeresh + Samudra | Q10: Completed | T10: Vivek | U10: Completed | X10: Sunil | Y10: Completed | AB10: Anji | AC10: Completed | AG10: NA | AK10: NA | AN10: No | AR10: =IF(AN10<>"Yes","",IF(AO10="","SELECT RE-ENTRY STAGE","MOVE TO ACTIVE at "&AO10)) | AS10: =IF(AN10="Yes",COUNTIF($AN$6:AN10,"Yes"),"") | AU10: =IF(OR(F10="Completed",F10="Cancelled"),"",IF(AND(OR(F10="On Hold",ISNUMBER(H10)),AT10=""),"Reason not given","")) | AV10: Completed the SI & PI and shared the reports. Performed the SI & PI for the DDR, PCIE_RC , PCIE_EPand DC_DROP and AC anlaysis.
A11: 6 | B11: GMR | C11: StationIs Rev1 | D11: Srinivas | E11: =IF(NOT(OR(M11="Completed",M11="NA",M11="Cancelled")),"S1 Schematic",IF(NOT(OR(Q11="Completed",Q11="NA",Q11="Cancelled")),"S2 PCB Layout",IF(NOT(OR(U11="Completed",U11="NA",U11="Cancelled")),"S3 SI & PI",IF(NOT(OR(Y11="Completed",Y11="NA",Y11="Cancelled")),"S4 Bare-PCB Fab",IF(NOT(OR(AC11="Completed",AC11="NA",AC11="Cancelled")),"S5 Assembly",IF(NOT(OR(AG11="Completed",AG11="NA",AG11="Cancelled")),"S6 Bring-up",IF(NOT(OR(AK11="Completed",AK11="NA",AK11="Cancelled")),"S7 BOM Procurement","All Stages Closed"))))))) -> All Stages Closed | F11: =IF(COUNTIF(M11,"Cancelled")+COUNTIF(Q11,"Cancelled")+COUNTIF(U11,"Cancelled")+COUNTIF(Y11,"Cancelled")+COUNTIF(AC11,"Cancelled")+COUNTIF(AG11,"Cancelled")+COUNTIF(AK11,"Cancelled")>0,"Cancelled",IF(E11="All Stages Closed","Completed",IF(E11="S1 Schematic",M11,IF(E11="S2 PCB Layout",Q11,IF(E11="S3 SI & PI",U11,IF(E11="S4 Bare-PCB Fab",Y11,IF(E11="S5 Assembly",AC11,IF(E11="S6 Bring-up",AG11,AK11)))))))) -> Completed | G11: =IF(E11="All Stages Closed","",IF(E11="S1 Schematic",IF(N11="","Not added",N11),IF(E11="S2 PCB Layout",IF(R11="","Not added",R11),IF(E11="S3 SI & PI",IF(V11="","Not added",V11),IF(E11="S4 Bare-PCB Fab",IF(Z11="","Not added",Z11),IF(E11="S5 Assembly",IF(AD11="","Not added",AD11),IF(E11="S6 Bring-up",IF(AH11="","Not added",AH11),IF(AL11="","Not added",AL11)))))))) | H11: =IF(OR(F11="Completed",F11="Cancelled"),"",IF(NOT(ISNUMBER(G11)),"Date not added",IF(TODAY()>G11,TODAY()-G11,G11-TODAY()&" days left"))) | I11: =COUNTIF(M11,"Completed")+COUNTIF(Q11,"Completed")+COUNTIF(U11,"Completed")+COUNTIF(Y11,"Completed")+COUNTIF(AC11,"Completed")+COUNTIF(AG11,"Completed")+COUNTIF(AK11,"Completed") -> 5 | J11: =7-(COUNTIF(M11,"NA")+COUNTIF(Q11,"NA")+COUNTIF(U11,"NA")+COUNTIF(Y11,"NA")+COUNTIF(AC11,"NA")+COUNTIF(AG11,"NA")+COUNTIF(AK11,"NA")) -> 5 | K11: =IFERROR(I11/J11,"") -> 1 | L11: Vardhan | M11: Completed | N11: 46254 | P11: Keerthi | Q11: Completed | T11: Vivek | U11: Completed | X11: Sunil | Y11: Completed | AB11: Anji | AC11: Completed | AG11: NA | AK11: NA | AN11: No | AR11: =IF(AN11<>"Yes","",IF(AO11="","SELECT RE-ENTRY STAGE","MOVE TO ACTIVE at "&AO11)) | AS11: =IF(AN11="Yes",COUNTIF($AN$6:AN11,"Yes"),"") | AU11: =IF(OR(F11="Completed",F11="Cancelled"),"",IF(AND(OR(F11="On Hold",ISNUMBER(H11)),AT11=""),"Reason not given","")) | AV11: Delivered
A12: 7 | B12: GMR | C12: StationIs Rev2 | D12: Srinivas | E12: =IF(NOT(OR(M12="Completed",M12="NA",M12="Cancelled")),"S1 Schematic",IF(NOT(OR(Q12="Completed",Q12="NA",Q12="Cancelled")),"S2 PCB Layout",IF(NOT(OR(U12="Completed",U12="NA",U12="Cancelled")),"S3 SI & PI",IF(NOT(OR(Y12="Completed",Y12="NA",Y12="Cancelled")),"S4 Bare-PCB Fab",IF(NOT(OR(AC12="Completed",AC12="NA",AC12="Cancelled")),"S5 Assembly",IF(NOT(OR(AG12="Completed",AG12="NA",AG12="Cancelled")),"S6 Bring-up",IF(NOT(OR(AK12="Completed",AK12="NA",AK12="Cancelled")),"S7 BOM Procurement","All Stages Closed"))))))) -> All Stages Closed | F12: =IF(COUNTIF(M12,"Cancelled")+COUNTIF(Q12,"Cancelled")+COUNTIF(U12,"Cancelled")+COUNTIF(Y12,"Cancelled")+COUNTIF(AC12,"Cancelled")+COUNTIF(AG12,"Cancelled")+COUNTIF(AK12,"Cancelled")>0,"Cancelled",IF(E12="All Stages Closed","Completed",IF(E12="S1 Schematic",M12,IF(E12="S2 PCB Layout",Q12,IF(E12="S3 SI & PI",U12,IF(E12="S4 Bare-PCB Fab",Y12,IF(E12="S5 Assembly",AC12,IF(E12="S6 Bring-up",AG12,AK12)))))))) -> Completed | G12: =IF(E12="All Stages Closed","",IF(E12="S1 Schematic",IF(N12="","Not added",N12),IF(E12="S2 PCB Layout",IF(R12="","Not added",R12),IF(E12="S3 SI & PI",IF(V12="","Not added",V12),IF(E12="S4 Bare-PCB Fab",IF(Z12="","Not added",Z12),IF(E12="S5 Assembly",IF(AD12="","Not added",AD12),IF(E12="S6 Bring-up",IF(AH12="","Not added",AH12),IF(AL12="","Not added",AL12)))))))) | H12: =IF(OR(F12="Completed",F12="Cancelled"),"",IF(NOT(ISNUMBER(G12)),"Date not added",IF(TODAY()>G12,TODAY()-G12,G12-TODAY()&" days left"))) | I12: =COUNTIF(M12,"Completed")+COUNTIF(Q12,"Completed")+COUNTIF(U12,"Completed")+COUNTIF(Y12,"Completed")+COUNTIF(AC12,"Completed")+COUNTIF(AG12,"Completed")+COUNTIF(AK12,"Completed") -> 5 | J12: =7-(COUNTIF(M12,"NA")+COUNTIF(Q12,"NA")+COUNTIF(U12,"NA")+COUNTIF(Y12,"NA")+COUNTIF(AC12,"NA")+COUNTIF(AG12,"NA")+COUNTIF(AK12,"NA")) -> 5 | K12: =IFERROR(I12/J12,"") -> 1 | L12: Vardhan | M12: Completed | N12: 46254 | P12: Keerthi | Q12: Completed | T12: NA | U12: Completed | X12: Sunil | Y12: Completed | AB12: Anji | AC12: Completed | AG12: NA | AK12: NA | AN12: No | AR12: =IF(AN12<>"Yes","",IF(AO12="","SELECT RE-ENTRY STAGE","MOVE TO ACTIVE at "&AO12)) | AS12: =IF(AN12="Yes",COUNTIF($AN$6:AN12,"Yes"),"") | AU12: =IF(OR(F12="Completed",F12="Cancelled"),"",IF(AND(OR(F12="On Hold",ISNUMBER(H12)),AT12=""),"Reason not given","")) | AV12: Delivered
A13: 8 | B13: GMR | C13: StationIs Rev3 | D13: Srinivas | E13: =IF(NOT(OR(M13="Completed",M13="NA",M13="Cancelled")),"S1 Schematic",IF(NOT(OR(Q13="Completed",Q13="NA",Q13="Cancelled")),"S2 PCB Layout",IF(NOT(OR(U13="Completed",U13="NA",U13="Cancelled")),"S3 SI & PI",IF(NOT(OR(Y13="Completed",Y13="NA",Y13="Cancelled")),"S4 Bare-PCB Fab",IF(NOT(OR(AC13="Completed",AC13="NA",AC13="Cancelled")),"S5 Assembly",IF(NOT(OR(AG13="Completed",AG13="NA",AG13="Cancelled")),"S6 Bring-up",IF(NOT(OR(AK13="Completed",AK13="NA",AK13="Cancelled")),"S7 BOM Procurement","All Stages Closed"))))))) -> All Stages Closed | F13: =IF(COUNTIF(M13,"Cancelled")+COUNTIF(Q13,"Cancelled")+COUNTIF(U13,"Cancelled")+COUNTIF(Y13,"Cancelled")+COUNTIF(AC13,"Cancelled")+COUNTIF(AG13,"Cancelled")+COUNTIF(AK13,"Cancelled")>0,"Cancelled",IF(E13="All Stages Closed","Completed",IF(E13="S1 Schematic",M13,IF(E13="S2 PCB Layout",Q13,IF(E13="S3 SI & PI",U13,IF(E13="S4 Bare-PCB Fab",Y13,IF(E13="S5 Assembly",AC13,IF(E13="S6 Bring-up",AG13,AK13)))))))) -> Completed | G13: =IF(E13="All Stages Closed","",IF(E13="S1 Schematic",IF(N13="","Not added",N13),IF(E13="S2 PCB Layout",IF(R13="","Not added",R13),IF(E13="S3 SI & PI",IF(V13="","Not added",V13),IF(E13="S4 Bare-PCB Fab",IF(Z13="","Not added",Z13),IF(E13="S5 Assembly",IF(AD13="","Not added",AD13),IF(E13="S6 Bring-up",IF(AH13="","Not added",AH13),IF(AL13="","Not added",AL13)))))))) | H13: =IF(OR(F13="Completed",F13="Cancelled"),"",IF(NOT(ISNUMBER(G13)),"Date not added",IF(TODAY()>G13,TODAY()-G13,G13-TODAY()&" days left"))) | I13: =COUNTIF(M13,"Completed")+COUNTIF(Q13,"Completed")+COUNTIF(U13,"Completed")+COUNTIF(Y13,"Completed")+COUNTIF(AC13,"Completed")+COUNTIF(AG13,"Completed")+COUNTIF(AK13,"Completed") -> 5 | J13: =7-(COUNTIF(M13,"NA")+COUNTIF(Q13,"NA")+COUNTIF(U13,"NA")+COUNTIF(Y13,"NA")+COUNTIF(AC13,"NA")+COUNTIF(AG13,"NA")+COUNTIF(AK13,"NA")) -> 5 | K13: =IFERROR(I13/J13,"") -> 1 | L13: Vardhan | M13: Completed | N13: 46254 | P13: Keerthi | Q13: Completed | T13: NA | U13: Completed | X13: Sunil | Y13: Completed | AB13: Anji | AC13: Completed | AG13: NA | AK13: NA | AN13: No | AR13: =IF(AN13<>"Yes","",IF(AO13="","SELECT RE-ENTRY STAGE","MOVE TO ACTIVE at "&AO13)) | AS13: =IF(AN13="Yes",COUNTIF($AN$6:AN13,"Yes"),"") | AU13: =IF(OR(F13="Completed",F13="Cancelled"),"",IF(AND(OR(F13="On Hold",ISNUMBER(H13)),AT13=""),"Reason not given",""))
A14: 9 | B14: HAL | C14: HAL_PCB_RE | D14: Rajesh | E14: =IF(NOT(OR(M14="Completed",M14="NA",M14="Cancelled")),"S1 Schematic",IF(NOT(OR(Q14="Completed",Q14="NA",Q14="Cancelled")),"S2 PCB Layout",IF(NOT(OR(U14="Completed",U14="NA",U14="Cancelled")),"S3 SI & PI",IF(NOT(OR(Y14="Completed",Y14="NA",Y14="Cancelled")),"S4 Bare-PCB Fab",IF(NOT(OR(AC14="Completed",AC14="NA",AC14="Cancelled")),"S5 Assembly",IF(NOT(OR(AG14="Completed",AG14="NA",AG14="Cancelled")),"S6 Bring-up",IF(NOT(OR(AK14="Completed",AK14="NA",AK14="Cancelled")),"S7 BOM Procurement","All Stages Closed"))))))) -> All Stages Closed | F14: =IF(COUNTIF(M14,"Cancelled")+COUNTIF(Q14,"Cancelled")+COUNTIF(U14,"Cancelled")+COUNTIF(Y14,"Cancelled")+COUNTIF(AC14,"Cancelled")+COUNTIF(AG14,"Cancelled")+COUNTIF(AK14,"Cancelled")>0,"Cancelled",IF(E14="All Stages Closed","Completed",IF(E14="S1 Schematic",M14,IF(E14="S2 PCB Layout",Q14,IF(E14="S3 SI & PI",U14,IF(E14="S4 Bare-PCB Fab",Y14,IF(E14="S5 Assembly",AC14,IF(E14="S6 Bring-up",AG14,AK14)))))))) -> Completed | G14: =IF(E14="All Stages Closed","",IF(E14="S1 Schematic",IF(N14="","Not added",N14),IF(E14="S2 PCB Layout",IF(R14="","Not added",R14),IF(E14="S3 SI & PI",IF(V14="","Not added",V14),IF(E14="S4 Bare-PCB Fab",IF(Z14="","Not added",Z14),IF(E14="S5 Assembly",IF(AD14="","Not added",AD14),IF(E14="S6 Bring-up",IF(AH14="","Not added",AH14),IF(AL14="","Not added",AL14)))))))) | H14: =IF(OR(F14="Completed",F14="Cancelled"),"",IF(NOT(ISNUMBER(G14)),"Date not added",IF(TODAY()>G14,TODAY()-G14,G14-TODAY()&" days left"))) | I14: =COUNTIF(M14,"Completed")+COUNTIF(Q14,"Completed")+COUNTIF(U14,"Completed")+COUNTIF(Y14,"Completed")+COUNTIF(AC14,"Completed")+COUNTIF(AG14,"Completed")+COUNTIF(AK14,"Completed") -> 1 | J14: =7-(COUNTIF(M14,"NA")+COUNTIF(Q14,"NA")+COUNTIF(U14,"NA")+COUNTIF(Y14,"NA")+COUNTIF(AC14,"NA")+COUNTIF(AG14,"NA")+COUNTIF(AK14,"NA")) -> 1 | K14: =IFERROR(I14/J14,"") -> 1 | M14: NA | P14: Vivek | Q14: Completed | R14: 46254 | U14: NA | Y14: NA | AC14: NA | AG14: NA | AK14: NA | AN14: No | AR14: =IF(AN14<>"Yes","",IF(AO14="","SELECT RE-ENTRY STAGE","MOVE TO ACTIVE at "&AO14)) | AS14: =IF(AN14="Yes",COUNTIF($AN$6:AN14,"Yes"),"") | AU14: =IF(OR(F14="Completed",F14="Cancelled"),"",IF(AND(OR(F14="On Hold",ISNUMBER(H14)),AT14=""),"Reason not given","")) | AV14: Anji | AW14: Completed
A15: 10 | B15: HAL | C15: IFF_BACKLIGHT_ILLUMINATION_BOARD. | D15: Srinivas L | E15: =IF(NOT(OR(M15="Completed",M15="NA",M15="Cancelled")),"S1 Schematic",IF(NOT(OR(Q15="Completed",Q15="NA",Q15="Cancelled")),"S2 PCB Layout",IF(NOT(OR(U15="Completed",U15="NA",U15="Cancelled")),"S3 SI & PI",IF(NOT(OR(Y15="Completed",Y15="NA",Y15="Cancelled")),"S4 Bare-PCB Fab",IF(NOT(OR(AC15="Completed",AC15="NA",AC15="Cancelled")),"S5 Assembly",IF(NOT(OR(AG15="Completed",AG15="NA",AG15="Cancelled")),"S6 Bring-up",IF(NOT(OR(AK15="Completed",AK15="NA",AK15="Cancelled")),"S7 BOM Procurement","All Stages Closed"))))))) -> All Stages Closed | F15: =IF(COUNTIF(M15,"Cancelled")+COUNTIF(Q15,"Cancelled")+COUNTIF(U15,"Cancelled")+COUNTIF(Y15,"Cancelled")+COUNTIF(AC15,"Cancelled")+COUNTIF(AG15,"Cancelled")+COUNTIF(AK15,"Cancelled")>0,"Cancelled",IF(E15="All Stages Closed","Completed",IF(E15="S1 Schematic",M15,IF(E15="S2 PCB Layout",Q15,IF(E15="S3 SI & PI",U15,IF(E15="S4 Bare-PCB Fab",Y15,IF(E15="S5 Assembly",AC15,IF(E15="S6 Bring-up",AG15,AK15)))))))) -> Completed | G15: =IF(E15="All Stages Closed","",IF(E15="S1 Schematic",IF(N15="","Not added",N15),IF(E15="S2 PCB Layout",IF(R15="","Not added",R15),IF(E15="S3 SI & PI",IF(V15="","Not added",V15),IF(E15="S4 Bare-PCB Fab",IF(Z15="","Not added",Z15),IF(E15="S5 Assembly",IF(AD15="","Not added",AD15),IF(E15="S6 Bring-up",IF(AH15="","Not added",AH15),IF(AL15="","Not added",AL15)))))))) | H15: =IF(OR(F15="Completed",F15="Cancelled"),"",IF(NOT(ISNUMBER(G15)),"Date not added",IF(TODAY()>G15,TODAY()-G15,G15-TODAY()&" days left"))) | I15: =COUNTIF(M15,"Completed")+COUNTIF(Q15,"Completed")+COUNTIF(U15,"Completed")+COUNTIF(Y15,"Completed")+COUNTIF(AC15,"Completed")+COUNTIF(AG15,"Completed")+COUNTIF(AK15,"Completed") -> 1 | J15: =7-(COUNTIF(M15,"NA")+COUNTIF(Q15,"NA")+COUNTIF(U15,"NA")+COUNTIF(Y15,"NA")+COUNTIF(AC15,"NA")+COUNTIF(AG15,"NA")+COUNTIF(AK15,"NA")) -> 1 | K15: =IFERROR(I15/J15,"") -> 1 | M15: NA | P15: Naveen | Q15: Completed | R15: 46241 | U15: NA | Y15: NA | AC15: NA | AG15: NA | AK15: NA | AN15: No | AR15: =IF(AN15<>"Yes","",IF(AO15="","SELECT RE-ENTRY STAGE","MOVE TO ACTIVE at "&AO15)) | AS15: =IF(AN15="Yes",COUNTIF($AN$6:AN15,"Yes"),"") | AU15: =IF(OR(F15="Completed",F15="Cancelled"),"",IF(AND(OR(F15="On Hold",ISNUMBER(H15)),AT15=""),"Reason not given","")) | AV15: Design completed, waiting for the customer feedback.
A16: 11 | B16: Internal | C16: NETRA_BASE_BOARD | D16: Rajesh | E16: =IF(NOT(OR(M16="Completed",M16="NA",M16="Cancelled")),"S1 Schematic",IF(NOT(OR(Q16="Completed",Q16="NA",Q16="Cancelled")),"S2 PCB Layout",IF(NOT(OR(U16="Completed",U16="NA",U16="Cancelled")),"S3 SI & PI",IF(NOT(OR(Y16="Completed",Y16="NA",Y16="Cancelled")),"S4 Bare-PCB Fab",IF(NOT(OR(AC16="Completed",AC16="NA",AC16="Cancelled")),"S5 Assembly",IF(NOT(OR(AG16="Completed",AG16="NA",AG16="Cancelled")),"S6 Bring-up",IF(NOT(OR(AK16="Completed",AK16="NA",AK16="Cancelled")),"S7 BOM Procurement","All Stages Closed"))))))) -> All Stages Closed | F16: =IF(COUNTIF(M16,"Cancelled")+COUNTIF(Q16,"Cancelled")+COUNTIF(U16,"Cancelled")+COUNTIF(Y16,"Cancelled")+COUNTIF(AC16,"Cancelled")+COUNTIF(AG16,"Cancelled")+COUNTIF(AK16,"Cancelled")>0,"Cancelled",IF(E16="All Stages Closed","Completed",IF(E16="S1 Schematic",M16,IF(E16="S2 PCB Layout",Q16,IF(E16="S3 SI & PI",U16,IF(E16="S4 Bare-PCB Fab",Y16,IF(E16="S5 Assembly",AC16,IF(E16="S6 Bring-up",AG16,AK16)))))))) -> Completed | G16: =IF(E16="All Stages Closed","",IF(E16="S1 Schematic",IF(N16="","Not added",N16),IF(E16="S2 PCB Layout",IF(R16="","Not added",R16),IF(E16="S3 SI & PI",IF(V16="","Not added",V16),IF(E16="S4 Bare-PCB Fab",IF(Z16="","Not added",Z16),IF(E16="S5 Assembly",IF(AD16="","Not added",AD16),IF(E16="S6 Bring-up",IF(AH16="","Not added",AH16),IF(AL16="","Not added",AL16)))))))) | H16: =IF(OR(F16="Completed",F16="Cancelled"),"",IF(NOT(ISNUMBER(G16)),"Date not added",IF(TODAY()>G16,TODAY()-G16,G16-TODAY()&" days left"))) | I16: =COUNTIF(M16,"Completed")+COUNTIF(Q16,"Completed")+COUNTIF(U16,"Completed")+COUNTIF(Y16,"Completed")+COUNTIF(AC16,"Completed")+COUNTIF(AG16,"Completed")+COUNTIF(AK16,"Completed") -> 5 | J16: =7-(COUNTIF(M16,"NA")+COUNTIF(Q16,"NA")+COUNTIF(U16,"NA")+COUNTIF(Y16,"NA")+COUNTIF(AC16,"NA")+COUNTIF(AG16,"NA")+COUNTIF(AK16,"NA")) -> 5 | K16: =IFERROR(I16/J16,"") -> 1 | L16: Harika | M16: Completed | N16: 46198 | P16: Sunil | Q16: Completed | R16: 46208 | T16: Vivek | U16: Completed | V16: 46209 | X16: JLC | Y16: Completed | Z16: 46218 | AC16: Completed | AG16: NA | AK16: NA | AN16: No | AR16: =IF(AN16<>"Yes","",IF(AO16="","SELECT RE-ENTRY STAGE","MOVE TO ACTIVE at "&AO16)) | AS16: =IF(AN16="Yes",COUNTIF($AN$6:AN16,"Yes"),"") | AU16: =IF(OR(F16="Completed",F16="Cancelled"),"",IF(AND(OR(F16="On Hold",ISNUMBER(H16)),AT16=""),"Reason not given","")) | AV16: Completed the DC Drop Analysis with JLC PCB Stackup. Completed the S-parameter extraction observed the severe impedance variation, return loss, NEXT, FEXT issues. Due to the connector
A17: 12 | B17: Internal | C17: Netra_Camera-Board_IMX463&IMX662 | D17: Prithvi | E17: =IF(NOT(OR(M17="Completed",M17="NA",M17="Cancelled")),"S1 Schematic",IF(NOT(OR(Q17="Completed",Q17="NA",Q17="Cancelled")),"S2 PCB Layout",IF(NOT(OR(U17="Completed",U17="NA",U17="Cancelled")),"S3 SI & PI",IF(NOT(OR(Y17="Completed",Y17="NA",Y17="Cancelled")),"S4 Bare-PCB Fab",IF(NOT(OR(AC17="Completed",AC17="NA",AC17="Cancelled")),"S5 Assembly",IF(NOT(OR(AG17="Completed",AG17="NA",AG17="Cancelled")),"S6 Bring-up",IF(NOT(OR(AK17="Completed",AK17="NA",AK17="Cancelled")),"S7 BOM Procurement","All Stages Closed"))))))) -> All Stages Closed | F17: =IF(COUNTIF(M17,"Cancelled")+COUNTIF(Q17,"Cancelled")+COUNTIF(U17,"Cancelled")+COUNTIF(Y17,"Cancelled")+COUNTIF(AC17,"Cancelled")+COUNTIF(AG17,"Cancelled")+COUNTIF(AK17,"Cancelled")>0,"Cancelled",IF(E17="All Stages Closed","Completed",IF(E17="S1 Schematic",M17,IF(E17="S2 PCB Layout",Q17,IF(E17="S3 SI & PI",U17,IF(E17="S4 Bare-PCB Fab",Y17,IF(E17="S5 Assembly",AC17,IF(E17="S6 Bring-up",AG17,AK17)))))))) -> Completed | G17: =IF(E17="All Stages Closed","",IF(E17="S1 Schematic",IF(N17="","Not added",N17),IF(E17="S2 PCB Layout",IF(R17="","Not added",R17),IF(E17="S3 SI & PI",IF(V17="","Not added",V17),IF(E17="S4 Bare-PCB Fab",IF(Z17="","Not added",Z17),IF(E17="S5 Assembly",IF(AD17="","Not added",AD17),IF(E17="S6 Bring-up",IF(AH17="","Not added",AH17),IF(AL17="","Not added",AL17)))))))) | H17: =IF(OR(F17="Completed",F17="Cancelled"),"",IF(NOT(ISNUMBER(G17)),"Date not added",IF(TODAY()>G17,TODAY()-G17,G17-TODAY()&" days left"))) | I17: =COUNTIF(M17,"Completed")+COUNTIF(Q17,"Completed")+COUNTIF(U17,"Completed")+COUNTIF(Y17,"Completed")+COUNTIF(AC17,"Completed")+COUNTIF(AG17,"Completed")+COUNTIF(AK17,"Completed") -> 5 | J17: =7-(COUNTIF(M17,"NA")+COUNTIF(Q17,"NA")+COUNTIF(U17,"NA")+COUNTIF(Y17,"NA")+COUNTIF(AC17,"NA")+COUNTIF(AG17,"NA")+COUNTIF(AK17,"NA")) -> 5 | K17: =IFERROR(I17/J17,"") -> 1 | L17: Harika | M17: Completed | P17: Srinivas | Q17: Completed | R17: 46209 | T17: Vivek | U17: Completed | X17: Sunil | Y17: Completed | AB17: Anji | AC17: Completed | AG17: NA | AK17: NA | AN17: No | AR17: =IF(AN17<>"Yes","",IF(AO17="","SELECT RE-ENTRY STAGE","MOVE TO ACTIVE at "&AO17)) | AS17: =IF(AN17="Yes",COUNTIF($AN$6:AN17,"Yes"),"") | AU17: =IF(OR(F17="Completed",F17="Cancelled"),"",IF(AND(OR(F17="On Hold",ISNUMBER(H17)),AT17=""),"Reason not given","")) | AV17: Pcb's Recevied | AW17: REVIEW: PCB row covers IMX463+IMX662 combined; schematic/fab rows are per-sensor
A18: 13 | B18: Internal | C18: Netra_Camera_ADDON | D18: Rajesh | E18: =IF(NOT(OR(M18="Completed",M18="NA",M18="Cancelled")),"S1 Schematic",IF(NOT(OR(Q18="Completed",Q18="NA",Q18="Cancelled")),"S2 PCB Layout",IF(NOT(OR(U18="Completed",U18="NA",U18="Cancelled")),"S3 SI & PI",IF(NOT(OR(Y18="Completed",Y18="NA",Y18="Cancelled")),"S4 Bare-PCB Fab",IF(NOT(OR(AC18="Completed",AC18="NA",AC18="Cancelled")),"S5 Assembly",IF(NOT(OR(AG18="Completed",AG18="NA",AG18="Cancelled")),"S6 Bring-up",IF(NOT(OR(AK18="Completed",AK18="NA",AK18="Cancelled")),"S7 BOM Procurement","All Stages Closed"))))))) -> All Stages Closed | F18: =IF(COUNTIF(M18,"Cancelled")+COUNTIF(Q18,"Cancelled")+COUNTIF(U18,"Cancelled")+COUNTIF(Y18,"Cancelled")+COUNTIF(AC18,"Cancelled")+COUNTIF(AG18,"Cancelled")+COUNTIF(AK18,"Cancelled")>0,"Cancelled",IF(E18="All Stages Closed","Completed",IF(E18="S1 Schematic",M18,IF(E18="S2 PCB Layout",Q18,IF(E18="S3 SI & PI",U18,IF(E18="S4 Bare-PCB Fab",Y18,IF(E18="S5 Assembly",AC18,IF(E18="S6 Bring-up",AG18,AK18)))))))) -> Completed | G18: =IF(E18="All Stages Closed","",IF(E18="S1 Schematic",IF(N18="","Not added",N18),IF(E18="S2 PCB Layout",IF(R18="","Not added",R18),IF(E18="S3 SI & PI",IF(V18="","Not added",V18),IF(E18="S4 Bare-PCB Fab",IF(Z18="","Not added",Z18),IF(E18="S5 Assembly",IF(AD18="","Not added",AD18),IF(E18="S6 Bring-up",IF(AH18="","Not added",AH18),IF(AL18="","Not added",AL18)))))))) | H18: =IF(OR(F18="Completed",F18="Cancelled"),"",IF(NOT(ISNUMBER(G18)),"Date not added",IF(TODAY()>G18,TODAY()-G18,G18-TODAY()&" days left"))) | I18: =COUNTIF(M18,"Completed")+COUNTIF(Q18,"Completed")+COUNTIF(U18,"Completed")+COUNTIF(Y18,"Completed")+COUNTIF(AC18,"Completed")+COUNTIF(AG18,"Completed")+COUNTIF(AK18,"Completed") -> 5 | J18: =7-(COUNTIF(M18,"NA")+COUNTIF(Q18,"NA")+COUNTIF(U18,"NA")+COUNTIF(Y18,"NA")+COUNTIF(AC18,"NA")+COUNTIF(AG18,"NA")+COUNTIF(AK18,"NA")) -> 5 | K18: =IFERROR(I18/J18,"") -> 1 | L18: Harika | M18: Completed | P18: Srinivas | Q18: Completed | T18: Vivek | U18: Completed | X18: Sunil | Y18: Completed | AB18: Anji | AC18: Completed | AG18: NA | AK18: NA | AN18: No | AR18: =IF(AN18<>"Yes","",IF(AO18="","SELECT RE-ENTRY STAGE","MOVE TO ACTIVE at "&AO18)) | AS18: =IF(AN18="Yes",COUNTIF($AN$6:AN18,"Yes"),"") | AU18: =IF(OR(F18="Completed",F18="Cancelled"),"",IF(AND(OR(F18="On Hold",ISNUMBER(H18)),AT18=""),"Reason not given","")) | AV18: Completed the S-parameter extraction observed the severe impedance variation, return loss, NEXT, FEXT issues. Due to the connector | AW18: REVIEW: SI&PI row does not identify which camera add-on
A19: 14 | B19: Internal | C19: Netra_Camera_AddOn_IMX462 | D19: Rajesh | E19: =IF(NOT(OR(M19="Completed",M19="NA",M19="Cancelled")),"S1 Schematic",IF(NOT(OR(Q19="Completed",Q19="NA",Q19="Cancelled")),"S2 PCB Layout",IF(NOT(OR(U19="Completed",U19="NA",U19="Cancelled")),"S3 SI & PI",IF(NOT(OR(Y19="Completed",Y19="NA",Y19="Cancelled")),"S4 Bare-PCB Fab",IF(NOT(OR(AC19="Completed",AC19="NA",AC19="Cancelled")),"S5 Assembly",IF(NOT(OR(AG19="Completed",AG19="NA",AG19="Cancelled")),"S6 Bring-up",IF(NOT(OR(AK19="Completed",AK19="NA",AK19="Cancelled")),"S7 BOM Procurement","All Stages Closed"))))))) -> All Stages Closed | F19: =IF(COUNTIF(M19,"Cancelled")+COUNTIF(Q19,"Cancelled")+COUNTIF(U19,"Cancelled")+COUNTIF(Y19,"Cancelled")+COUNTIF(AC19,"Cancelled")+COUNTIF(AG19,"Cancelled")+COUNTIF(AK19,"Cancelled")>0,"Cancelled",IF(E19="All Stages Closed","Completed",IF(E19="S1 Schematic",M19,IF(E19="S2 PCB Layout",Q19,IF(E19="S3 SI & PI",U19,IF(E19="S4 Bare-PCB Fab",Y19,IF(E19="S5 Assembly",AC19,IF(E19="S6 Bring-up",AG19,AK19)))))))) -> Completed | G19: =IF(E19="All Stages Closed","",IF(E19="S1 Schematic",IF(N19="","Not added",N19),IF(E19="S2 PCB Layout",IF(R19="","Not added",R19),IF(E19="S3 SI & PI",IF(V19="","Not added",V19),IF(E19="S4 Bare-PCB Fab",IF(Z19="","Not added",Z19),IF(E19="S5 Assembly",IF(AD19="","Not added",AD19),IF(E19="S6 Bring-up",IF(AH19="","Not added",AH19),IF(AL19="","Not added",AL19)))))))) | H19: =IF(OR(F19="Completed",F19="Cancelled"),"",IF(NOT(ISNUMBER(G19)),"Date not added",IF(TODAY()>G19,TODAY()-G19,G19-TODAY()&" days left"))) | I19: =COUNTIF(M19,"Completed")+COUNTIF(Q19,"Completed")+COUNTIF(U19,"Completed")+COUNTIF(Y19,"Completed")+COUNTIF(AC19,"Completed")+COUNTIF(AG19,"Completed")+COUNTIF(AK19,"Completed") -> 5 | J19: =7-(COUNTIF(M19,"NA")+COUNTIF(Q19,"NA")+COUNTIF(U19,"NA")+COUNTIF(Y19,"NA")+COUNTIF(AC19,"NA")+COUNTIF(AG19,"NA")+COUNTIF(AK19,"NA")) -> 5 | K19: =IFERROR(I19/J19,"") -> 1 | L19: Harika | M19: Completed | N19: 46203 | P19: Srinivas | Q19: Completed | T19: Vivek | U19: Completed | X19: Sunil | Y19: Completed | AB19: Anji | AC19: Completed | AG19: NA | AK19: NA | AN19: No | AR19: =IF(AN19<>"Yes","",IF(AO19="","SELECT RE-ENTRY STAGE","MOVE TO ACTIVE at "&AO19)) | AS19: =IF(AN19="Yes",COUNTIF($AN$6:AN19,"Yes"),"") | AU19: =IF(OR(F19="Completed",F19="Cancelled"),"",IF(AND(OR(F19="On Hold",ISNUMBER(H19)),AT19=""),"Reason not given",""))
A20: 15 | B20: Internal | C20: Netra_Camera_AddOn_IMX662 | D20: Rajesh | E20: =IF(NOT(OR(M20="Completed",M20="NA",M20="Cancelled")),"S1 Schematic",IF(NOT(OR(Q20="Completed",Q20="NA",Q20="Cancelled")),"S2 PCB Layout",IF(NOT(OR(U20="Completed",U20="NA",U20="Cancelled")),"S3 SI & PI",IF(NOT(OR(Y20="Completed",Y20="NA",Y20="Cancelled")),"S4 Bare-PCB Fab",IF(NOT(OR(AC20="Completed",AC20="NA",AC20="Cancelled")),"S5 Assembly",IF(NOT(OR(AG20="Completed",AG20="NA",AG20="Cancelled")),"S6 Bring-up",IF(NOT(OR(AK20="Completed",AK20="NA",AK20="Cancelled")),"S7 BOM Procurement","All Stages Closed"))))))) -> All Stages Closed | F20: =IF(COUNTIF(M20,"Cancelled")+COUNTIF(Q20,"Cancelled")+COUNTIF(U20,"Cancelled")+COUNTIF(Y20,"Cancelled")+COUNTIF(AC20,"Cancelled")+COUNTIF(AG20,"Cancelled")+COUNTIF(AK20,"Cancelled")>0,"Cancelled",IF(E20="All Stages Closed","Completed",IF(E20="S1 Schematic",M20,IF(E20="S2 PCB Layout",Q20,IF(E20="S3 SI & PI",U20,IF(E20="S4 Bare-PCB Fab",Y20,IF(E20="S5 Assembly",AC20,IF(E20="S6 Bring-up",AG20,AK20)))))))) -> Completed | G20: =IF(E20="All Stages Closed","",IF(E20="S1 Schematic",IF(N20="","Not added",N20),IF(E20="S2 PCB Layout",IF(R20="","Not added",R20),IF(E20="S3 SI & PI",IF(V20="","Not added",V20),IF(E20="S4 Bare-PCB Fab",IF(Z20="","Not added",Z20),IF(E20="S5 Assembly",IF(AD20="","Not added",AD20),IF(E20="S6 Bring-up",IF(AH20="","Not added",AH20),IF(AL20="","Not added",AL20)))))))) | H20: =IF(OR(F20="Completed",F20="Cancelled"),"",IF(NOT(ISNUMBER(G20)),"Date not added",IF(TODAY()>G20,TODAY()-G20,G20-TODAY()&" days left"))) | I20: =COUNTIF(M20,"Completed")+COUNTIF(Q20,"Completed")+COUNTIF(U20,"Completed")+COUNTIF(Y20,"Completed")+COUNTIF(AC20,"Completed")+COUNTIF(AG20,"Completed")+COUNTIF(AK20,"Completed") -> 5 | J20: =7-(COUNTIF(M20,"NA")+COUNTIF(Q20,"NA")+COUNTIF(U20,"NA")+COUNTIF(Y20,"NA")+COUNTIF(AC20,"NA")+COUNTIF(AG20,"NA")+COUNTIF(AK20,"NA")) -> 5 | K20: =IFERROR(I20/J20,"") -> 1 | L20: Harika | M20: Completed | N20: 46203 | P20: Srinivas | Q20: Completed | T20: Vivek | U20: Completed | X20: Sunil | Y20: Completed | AB20: Anji | AC20: Completed | AG20: NA | AK20: NA | AN20: No | AR20: =IF(AN20<>"Yes","",IF(AO20="","SELECT RE-ENTRY STAGE","MOVE TO ACTIVE at "&AO20)) | AS20: =IF(AN20="Yes",COUNTIF($AN$6:AN20,"Yes"),"") | AU20: =IF(OR(F20="Completed",F20="Cancelled"),"",IF(AND(OR(F20="On Hold",ISNUMBER(H20)),AT20=""),"Reason not given",""))
A21: 16 | B21: Internal | C21: Netra_LDR-Board | D21: Prithvi | E21: =IF(NOT(OR(M21="Completed",M21="NA",M21="Cancelled")),"S1 Schematic",IF(NOT(OR(Q21="Completed",Q21="NA",Q21="Cancelled")),"S2 PCB Layout",IF(NOT(OR(U21="Completed",U21="NA",U21="Cancelled")),"S3 SI & PI",IF(NOT(OR(Y21="Completed",Y21="NA",Y21="Cancelled")),"S4 Bare-PCB Fab",IF(NOT(OR(AC21="Completed",AC21="NA",AC21="Cancelled")),"S5 Assembly",IF(NOT(OR(AG21="Completed",AG21="NA",AG21="Cancelled")),"S6 Bring-up",IF(NOT(OR(AK21="Completed",AK21="NA",AK21="Cancelled")),"S7 BOM Procurement","All Stages Closed"))))))) -> All Stages Closed | F21: =IF(COUNTIF(M21,"Cancelled")+COUNTIF(Q21,"Cancelled")+COUNTIF(U21,"Cancelled")+COUNTIF(Y21,"Cancelled")+COUNTIF(AC21,"Cancelled")+COUNTIF(AG21,"Cancelled")+COUNTIF(AK21,"Cancelled")>0,"Cancelled",IF(E21="All Stages Closed","Completed",IF(E21="S1 Schematic",M21,IF(E21="S2 PCB Layout",Q21,IF(E21="S3 SI & PI",U21,IF(E21="S4 Bare-PCB Fab",Y21,IF(E21="S5 Assembly",AC21,IF(E21="S6 Bring-up",AG21,AK21)))))))) -> Completed | G21: =IF(E21="All Stages Closed","",IF(E21="S1 Schematic",IF(N21="","Not added",N21),IF(E21="S2 PCB Layout",IF(R21="","Not added",R21),IF(E21="S3 SI & PI",IF(V21="","Not added",V21),IF(E21="S4 Bare-PCB Fab",IF(Z21="","Not added",Z21),IF(E21="S5 Assembly",IF(AD21="","Not added",AD21),IF(E21="S6 Bring-up",IF(AH21="","Not added",AH21),IF(AL21="","Not added",AL21)))))))) | H21: =IF(OR(F21="Completed",F21="Cancelled"),"",IF(NOT(ISNUMBER(G21)),"Date not added",IF(TODAY()>G21,TODAY()-G21,G21-TODAY()&" days left"))) | I21: =COUNTIF(M21,"Completed")+COUNTIF(Q21,"Completed")+COUNTIF(U21,"Completed")+COUNTIF(Y21,"Completed")+COUNTIF(AC21,"Completed")+COUNTIF(AG21,"Completed")+COUNTIF(AK21,"Completed") -> 5 | J21: =7-(COUNTIF(M21,"NA")+COUNTIF(Q21,"NA")+COUNTIF(U21,"NA")+COUNTIF(Y21,"NA")+COUNTIF(AC21,"NA")+COUNTIF(AG21,"NA")+COUNTIF(AK21,"NA")) -> 5 | K21: =IFERROR(I21/J21,"") -> 1 | L21: Harika | M21: Completed | N21: 46202 | P21: Srinivas | Q21: Completed | T21: Vivek | U21: Completed | X21: Pcb Power | Y21: Completed | Z21: 46213 | AB21: Anji | AC21: Completed | AG21: NA | AK21: NA | AN21: No | AR21: =IF(AN21<>"Yes","",IF(AO21="","SELECT RE-ENTRY STAGE","MOVE TO ACTIVE at "&AO21)) | AS21: =IF(AN21="Yes",COUNTIF($AN$6:AN21,"Yes"),"") | AU21: =IF(OR(F21="Completed",F21="Cancelled"),"",IF(AND(OR(F21="On Hold",ISNUMBER(H21)),AT21=""),"Reason not given","")) | AV21: Pcb's Recevied | AW21: Schematic row "NETRA_LDR-IR" merged here
A22: 17 | B22: Internal | C22: Netra_POE-Board | D22: Prithvi | E22: =IF(NOT(OR(M22="Completed",M22="NA",M22="Cancelled")),"S1 Schematic",IF(NOT(OR(Q22="Completed",Q22="NA",Q22="Cancelled")),"S2 PCB Layout",IF(NOT(OR(U22="Completed",U22="NA",U22="Cancelled")),"S3 SI & PI",IF(NOT(OR(Y22="Completed",Y22="NA",Y22="Cancelled")),"S4 Bare-PCB Fab",IF(NOT(OR(AC22="Completed",AC22="NA",AC22="Cancelled")),"S5 Assembly",IF(NOT(OR(AG22="Completed",AG22="NA",AG22="Cancelled")),"S6 Bring-up",IF(NOT(OR(AK22="Completed",AK22="NA",AK22="Cancelled")),"S7 BOM Procurement","All Stages Closed"))))))) -> All Stages Closed | F22: =IF(COUNTIF(M22,"Cancelled")+COUNTIF(Q22,"Cancelled")+COUNTIF(U22,"Cancelled")+COUNTIF(Y22,"Cancelled")+COUNTIF(AC22,"Cancelled")+COUNTIF(AG22,"Cancelled")+COUNTIF(AK22,"Cancelled")>0,"Cancelled",IF(E22="All Stages Closed","Completed",IF(E22="S1 Schematic",M22,IF(E22="S2 PCB Layout",Q22,IF(E22="S3 SI & PI",U22,IF(E22="S4 Bare-PCB Fab",Y22,IF(E22="S5 Assembly",AC22,IF(E22="S6 Bring-up",AG22,AK22)))))))) -> Completed | G22: =IF(E22="All Stages Closed","",IF(E22="S1 Schematic",IF(N22="","Not added",N22),IF(E22="S2 PCB Layout",IF(R22="","Not added",R22),IF(E22="S3 SI & PI",IF(V22="","Not added",V22),IF(E22="S4 Bare-PCB Fab",IF(Z22="","Not added",Z22),IF(E22="S5 Assembly",IF(AD22="","Not added",AD22),IF(E22="S6 Bring-up",IF(AH22="","Not added",AH22),IF(AL22="","Not added",AL22)))))))) | H22: =IF(OR(F22="Completed",F22="Cancelled"),"",IF(NOT(ISNUMBER(G22)),"Date not added",IF(TODAY()>G22,TODAY()-G22,G22-TODAY()&" days left"))) | I22: =COUNTIF(M22,"Completed")+COUNTIF(Q22,"Completed")+COUNTIF(U22,"Completed")+COUNTIF(Y22,"Completed")+COUNTIF(AC22,"Completed")+COUNTIF(AG22,"Completed")+COUNTIF(AK22,"Completed") -> 5 | J22: =7-(COUNTIF(M22,"NA")+COUNTIF(Q22,"NA")+COUNTIF(U22,"NA")+COUNTIF(Y22,"NA")+COUNTIF(AC22,"NA")+COUNTIF(AG22,"NA")+COUNTIF(AK22,"NA")) -> 5 | K22: =IFERROR(I22/J22,"") -> 1 | L22: Harika | M22: Completed | N22: 46199 | P22: Srinivas | Q22: Completed | T22: Vivek | U22: Completed | X22: Pcb Power | Y22: Completed | Z22: 46213 | AB22: Anji | AC22: Completed | AG22: NA | AK22: NA | AN22: No | AR22: =IF(AN22<>"Yes","",IF(AO22="","SELECT RE-ENTRY STAGE","MOVE TO ACTIVE at "&AO22)) | AS22: =IF(AN22="Yes",COUNTIF($AN$6:AN22,"Yes"),"") | AU22: =IF(OR(F22="Completed",F22="Cancelled"),"",IF(AND(OR(F22="On Hold",ISNUMBER(H22)),AT22=""),"Reason not given","")) | AV22: Pcb's Recevied | AW22: Schematic "NETRA_POE" merged here
A23: 18 | B23: Internal | C23: Netra_POE_MP8007 | D23: Prithvi | E23: =IF(NOT(OR(M23="Completed",M23="NA",M23="Cancelled")),"S1 Schematic",IF(NOT(OR(Q23="Completed",Q23="NA",Q23="Cancelled")),"S2 PCB Layout",IF(NOT(OR(U23="Completed",U23="NA",U23="Cancelled")),"S3 SI & PI",IF(NOT(OR(Y23="Completed",Y23="NA",Y23="Cancelled")),"S4 Bare-PCB Fab",IF(NOT(OR(AC23="Completed",AC23="NA",AC23="Cancelled")),"S5 Assembly",IF(NOT(OR(AG23="Completed",AG23="NA",AG23="Cancelled")),"S6 Bring-up",IF(NOT(OR(AK23="Completed",AK23="NA",AK23="Cancelled")),"S7 BOM Procurement","All Stages Closed"))))))) -> All Stages Closed | F23: =IF(COUNTIF(M23,"Cancelled")+COUNTIF(Q23,"Cancelled")+COUNTIF(U23,"Cancelled")+COUNTIF(Y23,"Cancelled")+COUNTIF(AC23,"Cancelled")+COUNTIF(AG23,"Cancelled")+COUNTIF(AK23,"Cancelled")>0,"Cancelled",IF(E23="All Stages Closed","Completed",IF(E23="S1 Schematic",M23,IF(E23="S2 PCB Layout",Q23,IF(E23="S3 SI & PI",U23,IF(E23="S4 Bare-PCB Fab",Y23,IF(E23="S5 Assembly",AC23,IF(E23="S6 Bring-up",AG23,AK23)))))))) -> Completed | G23: =IF(E23="All Stages Closed","",IF(E23="S1 Schematic",IF(N23="","Not added",N23),IF(E23="S2 PCB Layout",IF(R23="","Not added",R23),IF(E23="S3 SI & PI",IF(V23="","Not added",V23),IF(E23="S4 Bare-PCB Fab",IF(Z23="","Not added",Z23),IF(E23="S5 Assembly",IF(AD23="","Not added",AD23),IF(E23="S6 Bring-up",IF(AH23="","Not added",AH23),IF(AL23="","Not added",AL23)))))))) | H23: =IF(OR(F23="Completed",F23="Cancelled"),"",IF(NOT(ISNUMBER(G23)),"Date not added",IF(TODAY()>G23,TODAY()-G23,G23-TODAY()&" days left"))) | I23: =COUNTIF(M23,"Completed")+COUNTIF(Q23,"Completed")+COUNTIF(U23,"Completed")+COUNTIF(Y23,"Completed")+COUNTIF(AC23,"Completed")+COUNTIF(AG23,"Completed")+COUNTIF(AK23,"Completed") -> 5 | J23: =7-(COUNTIF(M23,"NA")+COUNTIF(Q23,"NA")+COUNTIF(U23,"NA")+COUNTIF(Y23,"NA")+COUNTIF(AC23,"NA")+COUNTIF(AG23,"NA")+COUNTIF(AK23,"NA")) -> 5 | K23: =IFERROR(I23/J23,"") -> 1 | L23: Harika | M23: Completed | P23: Srinivas | Q23: Completed | T23: Vivek | U23: Completed | X23: Sunil | Y23: Completed | AB23: Anji | AC23: Completed | AG23: NA | AK23: NA | AN23: No | AR23: =IF(AN23<>"Yes","",IF(AO23="","SELECT RE-ENTRY STAGE","MOVE TO ACTIVE at "&AO23)) | AS23: =IF(AN23="Yes",COUNTIF($AN$6:AN23,"Yes"),"") | AU23: =IF(OR(F23="Completed",F23="Cancelled"),"",IF(AND(OR(F23="On Hold",ISNUMBER(H23)),AT23=""),"Reason not given","")) | AV23: Project completed
A24: 19 | B24: Internal | C24: Netra_SD_Board | D24: Prithvi | E24: =IF(NOT(OR(M24="Completed",M24="NA",M24="Cancelled")),"S1 Schematic",IF(NOT(OR(Q24="Completed",Q24="NA",Q24="Cancelled")),"S2 PCB Layout",IF(NOT(OR(U24="Completed",U24="NA",U24="Cancelled")),"S3 SI & PI",IF(NOT(OR(Y24="Completed",Y24="NA",Y24="Cancelled")),"S4 Bare-PCB Fab",IF(NOT(OR(AC24="Completed",AC24="NA",AC24="Cancelled")),"S5 Assembly",IF(NOT(OR(AG24="Completed",AG24="NA",AG24="Cancelled")),"S6 Bring-up",IF(NOT(OR(AK24="Completed",AK24="NA",AK24="Cancelled")),"S7 BOM Procurement","All Stages Closed"))))))) -> All Stages Closed | F24: =IF(COUNTIF(M24,"Cancelled")+COUNTIF(Q24,"Cancelled")+COUNTIF(U24,"Cancelled")+COUNTIF(Y24,"Cancelled")+COUNTIF(AC24,"Cancelled")+COUNTIF(AG24,"Cancelled")+COUNTIF(AK24,"Cancelled")>0,"Cancelled",IF(E24="All Stages Closed","Completed",IF(E24="S1 Schematic",M24,IF(E24="S2 PCB Layout",Q24,IF(E24="S3 SI & PI",U24,IF(E24="S4 Bare-PCB Fab",Y24,IF(E24="S5 Assembly",AC24,IF(E24="S6 Bring-up",AG24,AK24)))))))) -> Completed | G24: =IF(E24="All Stages Closed","",IF(E24="S1 Schematic",IF(N24="","Not added",N24),IF(E24="S2 PCB Layout",IF(R24="","Not added",R24),IF(E24="S3 SI & PI",IF(V24="","Not added",V24),IF(E24="S4 Bare-PCB Fab",IF(Z24="","Not added",Z24),IF(E24="S5 Assembly",IF(AD24="","Not added",AD24),IF(E24="S6 Bring-up",IF(AH24="","Not added",AH24),IF(AL24="","Not added",AL24)))))))) | H24: =IF(OR(F24="Completed",F24="Cancelled"),"",IF(NOT(ISNUMBER(G24)),"Date not added",IF(TODAY()>G24,TODAY()-G24,G24-TODAY()&" days left"))) | I24: =COUNTIF(M24,"Completed")+COUNTIF(Q24,"Completed")+COUNTIF(U24,"Completed")+COUNTIF(Y24,"Completed")+COUNTIF(AC24,"Completed")+COUNTIF(AG24,"Completed")+COUNTIF(AK24,"Completed") -> 5 | J24: =7-(COUNTIF(M24,"NA")+COUNTIF(Q24,"NA")+COUNTIF(U24,"NA")+COUNTIF(Y24,"NA")+COUNTIF(AC24,"NA")+COUNTIF(AG24,"NA")+COUNTIF(AK24,"NA")) -> 5 | K24: =IFERROR(I24/J24,"") -> 1 | L24: Harika | M24: Completed | N24: 46203 | P24: Srinivas | Q24: Completed | R24: 46209 | T24: Vivek | U24: Completed | X24: Pcb Power | Y24: Completed | Z24: 46213 | AB24: Anji | AC24: Completed | AG24: NA | AK24: NA | AN24: No | AR24: =IF(AN24<>"Yes","",IF(AO24="","SELECT RE-ENTRY STAGE","MOVE TO ACTIVE at "&AO24)) | AS24: =IF(AN24="Yes",COUNTIF($AN$6:AN24,"Yes"),"") | AU24: =IF(OR(F24="Completed",F24="Cancelled"),"",IF(AND(OR(F24="On Hold",ISNUMBER(H24)),AT24=""),"Reason not given","")) | AV24: Pcb's Recevied | AW24: Schematic "NETRA_SD CARD" + fab "Netra_SD_Card_Board" merged
A25: 20 | B25: Internal | C25: RZV2N_Addon_Card | D25: Rajesh | E25: =IF(NOT(OR(M25="Completed",M25="NA",M25="Cancelled")),"S1 Schematic",IF(NOT(OR(Q25="Completed",Q25="NA",Q25="Cancelled")),"S2 PCB Layout",IF(NOT(OR(U25="Completed",U25="NA",U25="Cancelled")),"S3 SI & PI",IF(NOT(OR(Y25="Completed",Y25="NA",Y25="Cancelled")),"S4 Bare-PCB Fab",IF(NOT(OR(AC25="Completed",AC25="NA",AC25="Cancelled")),"S5 Assembly",IF(NOT(OR(AG25="Completed",AG25="NA",AG25="Cancelled")),"S6 Bring-up",IF(NOT(OR(AK25="Completed",AK25="NA",AK25="Cancelled")),"S7 BOM Procurement","All Stages Closed"))))))) -> All Stages Closed | F25: =IF(COUNTIF(M25,"Cancelled")+COUNTIF(Q25,"Cancelled")+COUNTIF(U25,"Cancelled")+COUNTIF(Y25,"Cancelled")+COUNTIF(AC25,"Cancelled")+COUNTIF(AG25,"Cancelled")+COUNTIF(AK25,"Cancelled")>0,"Cancelled",IF(E25="All Stages Closed","Completed",IF(E25="S1 Schematic",M25,IF(E25="S2 PCB Layout",Q25,IF(E25="S3 SI & PI",U25,IF(E25="S4 Bare-PCB Fab",Y25,IF(E25="S5 Assembly",AC25,IF(E25="S6 Bring-up",AG25,AK25)))))))) -> Completed | G25: =IF(E25="All Stages Closed","",IF(E25="S1 Schematic",IF(N25="","Not added",N25),IF(E25="S2 PCB Layout",IF(R25="","Not added",R25),IF(E25="S3 SI & PI",IF(V25="","Not added",V25),IF(E25="S4 Bare-PCB Fab",IF(Z25="","Not added",Z25),IF(E25="S5 Assembly",IF(AD25="","Not added",AD25),IF(E25="S6 Bring-up",IF(AH25="","Not added",AH25),IF(AL25="","Not added",AL25)))))))) | H25: =IF(OR(F25="Completed",F25="Cancelled"),"",IF(NOT(ISNUMBER(G25)),"Date not added",IF(TODAY()>G25,TODAY()-G25,G25-TODAY()&" days left"))) | I25: =COUNTIF(M25,"Completed")+COUNTIF(Q25,"Completed")+COUNTIF(U25,"Completed")+COUNTIF(Y25,"Completed")+COUNTIF(AC25,"Completed")+COUNTIF(AG25,"Completed")+COUNTIF(AK25,"Completed") -> 5 | J25: =7-(COUNTIF(M25,"NA")+COUNTIF(Q25,"NA")+COUNTIF(U25,"NA")+COUNTIF(Y25,"NA")+COUNTIF(AC25,"NA")+COUNTIF(AG25,"NA")+COUNTIF(AK25,"NA")) -> 5 | K25: =IFERROR(I25/J25,"") -> 1 | L25: Veeresh | M25: Completed | N25: 46191 | P25: Naveen | Q25: Completed | R25: 46199 | T25: Vivek | U25: Completed | V25: 46201 | Y25: Completed | AC25: Completed | AG25: NA | AK25: NA | AN25: No | AR25: =IF(AN25<>"Yes","",IF(AO25="","SELECT RE-ENTRY STAGE","MOVE TO ACTIVE at "&AO25)) | AS25: =IF(AN25="Yes",COUNTIF($AN$6:AN25,"Yes"),"") | AU25: =IF(OR(F25="Completed",F25="Cancelled"),"",IF(AND(OR(F25="On Hold",ISNUMBER(H25)),AT25=""),"Reason not given","")) | AV25: Completed the SI Analysis for the Camera on card.
